<?xml version="1.0"?>
<sdf version='1.6'>
  <model name='multiple_robots'>
    <link name='arm_base_link'>
      <pose frame=''>0 -3 0 0 -0 0</pose>
      <inertial>
        <pose frame=''>0 0 0 0 -0 0</pose>
        <mass>0.29364</mass>
        <inertia>
          <ixx>0.01</ixx>
          <ixy>0</ixy>
          <ixz>0</ixz>
          <iyy>0.01</iyy>
          <iyz>0</iyz>
          <izz>0.01</izz>
        </inertia>
      </inertial>
      <collision name='arm_base_link_fixed_joint_lump__arm_0_link_collision'>
        <pose frame=''>0 0 0 0 -0 0</pose>
        <geometry>
          <mesh>
            <scale>1 1 1</scale>
            <uri>model://iiwa_panda_lwa4p_ur5e/meshes/lwa4p/arm_0_link.stl</uri>
          </mesh>
        </geometry>
        <surface>
          <contact>
            <ode/>
          </contact>
          <friction>
            <ode/>
          </friction>
        </surface>
      </collision>
      <visual name='arm_base_link_fixed_joint_lump__arm_0_link_visual'>
        <pose frame=''>0 0 0 0 -0 0</pose>
        <geometry>
          <mesh>
            <scale>1 1 1</scale>
            <uri>model://iiwa_panda_lwa4p_ur5e/meshes/lwa4p/arm_0_link.dae</uri>
          </mesh>
        </geometry>
        <material>
          <script>
            <name>Gazebo/Grey</name>
            <uri>file://media/materials/scripts/gazebo.material</uri>
          </script>
        </material>
      </visual>
      <gravity>1</gravity>
      <velocity_decay/>
      <self_collide>0</self_collide>
      <gravity>1</gravity>
    </link>
    <joint name='arm_base_joint' type='fixed'>
      <child>arm_base_link</child>
      <parent>world</parent>
    </joint>
    <link name='arm_1_link'>
      <pose frame=''>0 -3 0.11 0 -0 0</pose>
      <inertial>
        <pose frame=''>0 0 0 0 -0 0</pose>
        <mass>0.29364</mass>
        <inertia>
          <ixx>0.01</ixx>
          <ixy>0</ixy>
          <ixz>0</ixz>
          <iyy>0.01</iyy>
          <iyz>0</iyz>
          <izz>0.01</izz>
        </inertia>
      </inertial>
      <collision name='arm_1_link_collision'>
        <pose frame=''>0 0 0 0 -0 0</pose>
        <geometry>
          <mesh>
            <scale>1 1 1</scale>
            <uri>model://iiwa_panda_lwa4p_ur5e/meshes/lwa4p/arm_1_link.stl</uri>
          </mesh>
        </geometry>
        <surface>
          <contact>
            <ode/>
          </contact>
          <friction>
            <ode/>
          </friction>
        </surface>
      </collision>
      <visual name='arm_1_link_visual'>
        <pose frame=''>0 0 0 0 -0 0</pose>
        <geometry>
          <mesh>
            <scale>1 1 1</scale>
            <uri>model://iiwa_panda_lwa4p_ur5e/meshes/lwa4p/arm_1_link.dae</uri>
          </mesh>
        </geometry>
        <material>
          <script>
            <name>Gazebo/Grey</name>
            <uri>file://media/materials/scripts/gazebo.material</uri>
          </script>
        </material>
      </visual>
      <gravity>1</gravity>
      <velocity_decay/>
      <self_collide>1</self_collide>
      <gravity>1</gravity>
    </link>
    <joint name='arm_1_joint' type='revolute'>
      <child>arm_1_link</child>
      <parent>arm_base_link</parent>
      <axis>
        <xyz>0 0 1</xyz>
        <limit>
          <lower>-2.95</lower>
          <upper>2.95</upper>
          <effort>10000</effort>
          <velocity>1.25</velocity>
        </limit>
        <dynamics>
          <spring_reference>0</spring_reference>
          <spring_stiffness>0</spring_stiffness>
        </dynamics>
        <use_parent_model_frame>1</use_parent_model_frame>
      </axis>
    </joint>
    <link name='arm_2_link'>
      <pose frame=''>0 -3 0.11 1.5708 -0 0</pose>
      <inertial>
        <pose frame=''>0 0 0 0 -0 0</pose>
        <mass>0.29364</mass>
        <inertia>
          <ixx>0.01</ixx>
          <ixy>0</ixy>
          <ixz>0</ixz>
          <iyy>0.01</iyy>
          <iyz>0</iyz>
          <izz>0.01</izz>
        </inertia>
      </inertial>
      <collision name='arm_2_link_collision'>
        <pose frame=''>0 0 0 0 -0 0</pose>
        <geometry>
          <mesh>
            <scale>1 1 1</scale>
            <uri>model://iiwa_panda_lwa4p_ur5e/meshes/lwa4p/arm_2_link.stl</uri>
          </mesh>
        </geometry>
        <surface>
          <contact>
            <ode/>
          </contact>
          <friction>
            <ode/>
          </friction>
        </surface>
      </collision>
      <visual name='arm_2_link_visual'>
        <pose frame=''>0 0 0 0 -0 0</pose>
        <geometry>
          <mesh>
            <scale>1 1 1</scale>
            <uri>model://iiwa_panda_lwa4p_ur5e/meshes/lwa4p/arm_2_link.dae</uri>
          </mesh>
        </geometry>
        <material>
          <script>
            <name>Gazebo/Blue</name>
            <uri>file://media/materials/scripts/gazebo.material</uri>
          </script>
        </material>
      </visual>
      <gravity>1</gravity>
      <velocity_decay/>
      <self_collide>1</self_collide>
      <gravity>1</gravity>
    </link>
    <joint name='arm_2_joint' type='revolute'>
      <child>arm_2_link</child>
      <parent>arm_1_link</parent>
      <axis>
        <xyz>0 -1 -4e-06</xyz>
        <limit>
          <lower>-2.95</lower>
          <upper>2.95</upper>
          <effort>10000</effort>
          <velocity>1.25</velocity>
        </limit>
        <dynamics>
          <spring_reference>0</spring_reference>
          <spring_stiffness>0</spring_stiffness>
        </dynamics>
        <use_parent_model_frame>1</use_parent_model_frame>
      </axis>
    </joint>
    <link name='arm_3_link'>
      <pose frame=''>0 -3 0.46 1.57079 -0 3.14159</pose>
      <inertial>
        <pose frame=''>0 0 0 0 -0 0</pose>
        <mass>0.29364</mass>
        <inertia>
          <ixx>0.01</ixx>
          <ixy>0</ixy>
          <ixz>0</ixz>
          <iyy>0.01</iyy>
          <iyz>0</iyz>
          <izz>0.01</izz>
        </inertia>
      </inertial>
      <collision name='arm_3_link_collision'>
        <pose frame=''>0 0 0 0 -0 0</pose>
        <geometry>
          <mesh>
            <scale>1 1 1</scale>
            <uri>model://iiwa_panda_lwa4p_ur5e/meshes/lwa4p/arm_3_link.stl</uri>
          </mesh>
        </geometry>
        <surface>
          <contact>
            <ode/>
          </contact>
          <friction>
            <ode/>
          </friction>
        </surface>
      </collision>
      <visual name='arm_3_link_visual'>
        <pose frame=''>0 0 0 0 -0 0</pose>
        <geometry>
          <mesh>
            <scale>1 1 1</scale>
            <uri>model://iiwa_panda_lwa4p_ur5e/meshes/lwa4p/arm_3_link.dae</uri>
          </mesh>
        </geometry>
        <material>
          <script>
            <name>Gazebo/Grey</name>
            <uri>file://media/materials/scripts/gazebo.material</uri>
          </script>
        </material>
      </visual>
      <gravity>1</gravity>
      <velocity_decay/>
      <self_collide>1</self_collide>
      <gravity>1</gravity>
    </link>
    <joint name='arm_3_joint' type='revolute'>
      <child>arm_3_link</child>
      <parent>arm_2_link</parent>
      <axis>
        <xyz>3e-06 1 4e-06</xyz>
        <limit>
          <lower>-2.95</lower>
          <upper>2.95</upper>
          <effort>10000</effort>
          <velocity>1.25</velocity>
        </limit>
        <dynamics>
          <spring_reference>0</spring_reference>
          <spring_stiffness>0</spring_stiffness>
        </dynamics>
        <use_parent_model_frame>1</use_parent_model_frame>
      </axis>
    </joint>
    <link name='arm_4_link'>
      <pose frame=''>0 -3 0.46 -0 0 -5e-06</pose>
      <inertial>
        <pose frame=''>0 0 0 0 -0 0</pose>
        <mass>0.29364</mass>
        <inertia>
          <ixx>0.01</ixx>
          <ixy>0</ixy>
          <ixz>0</ixz>
          <iyy>0.01</iyy>
          <iyz>0</iyz>
          <izz>0.01</izz>
        </inertia>
      </inertial>
      <collision name='arm_4_link_collision'>
        <pose frame=''>0 0 0 0 -0 0</pose>
        <geometry>
          <mesh>
            <scale>1 1 1</scale>
            <uri>model://iiwa_panda_lwa4p_ur5e/meshes/lwa4p/arm_4_link.stl</uri>
          </mesh>
        </geometry>
        <surface>
          <contact>
            <ode/>
          </contact>
          <friction>
            <ode/>
          </friction>
        </surface>
      </collision>
      <visual name='arm_4_link_visual'>
        <pose frame=''>0 0 0 0 -0 0</pose>
        <geometry>
          <mesh>
            <scale>1 1 1</scale>
            <uri>model://iiwa_panda_lwa4p_ur5e/meshes/lwa4p/arm_4_link.dae</uri>
          </mesh>
        </geometry>
        <material>
          <script>
            <name>Gazebo/Blue</name>
            <uri>file://media/materials/scripts/gazebo.material</uri>
          </script>
        </material>
      </visual>
      <gravity>1</gravity>
      <velocity_decay/>
      <self_collide>1</self_collide>
      <gravity>1</gravity>
    </link>
    <joint name='arm_4_joint' type='revolute'>
      <child>arm_4_link</child>
      <parent>arm_3_link</parent>
      <axis>
        <xyz>0 -0 1</xyz>
        <limit>
          <lower>-2.95</lower>
          <upper>2.95</upper>
          <effort>10000</effort>
          <velocity>1.25</velocity>
        </limit>
        <dynamics>
          <spring_reference>0</spring_reference>
          <spring_stiffness>0</spring_stiffness>
        </dynamics>
        <use_parent_model_frame>1</use_parent_model_frame>
      </axis>
    </joint>
    <link name='arm_5_link'>
      <pose frame=''>0 -2.99474 0.765 1.5708 -0 3.14158</pose>
      <inertial>
        <pose frame=''>0 0 0 0 -0 0</pose>
        <mass>0.29364</mass>
        <inertia>
          <ixx>0.01</ixx>
          <ixy>0</ixy>
          <ixz>0</ixz>
          <iyy>0.01</iyy>
          <iyz>0</iyz>
          <izz>0.01</izz>
        </inertia>
      </inertial>
      <collision name='arm_5_link_collision'>
        <pose frame=''>0 0 0 0 -0 0</pose>
        <geometry>
          <mesh>
            <scale>1 1 1</scale>
            <uri>model://iiwa_panda_lwa4p_ur5e/meshes/lwa4p/arm_5_link.stl</uri>
          </mesh>
        </geometry>
        <surface>
          <contact>
            <ode/>
          </contact>
          <friction>
            <ode/>
          </friction>
        </surface>
      </collision>
      <visual name='arm_5_link_visual'>
        <pose frame=''>0 0 0 0 -0 0</pose>
        <geometry>
          <mesh>
            <scale>1 1 1</scale>
            <uri>model://iiwa_panda_lwa4p_ur5e/meshes/lwa4p/arm_5_link.dae</uri>
          </mesh>
        </geometry>
        <material>
          <script>
            <name>Gazebo/Grey</name>
            <uri>file://media/materials/scripts/gazebo.material</uri>
          </script>
        </material>
      </visual>
      <gravity>1</gravity>
      <velocity_decay/>
      <self_collide>1</self_collide>
      <gravity>1</gravity>
    </link>
    <joint name='arm_5_joint' type='revolute'>
      <child>arm_5_link</child>
      <parent>arm_4_link</parent>
      <axis>
        <xyz>8e-06 1 -4e-06</xyz>
        <limit>
          <lower>-2.95</lower>
          <upper>2.95</upper>
          <effort>10000</effort>
          <velocity>1.25</velocity>
        </limit>
        <dynamics>
          <spring_reference>0</spring_reference>
          <spring_stiffness>0</spring_stiffness>
        </dynamics>
        <use_parent_model_frame>1</use_parent_model_frame>
      </axis>
    </joint>
    <link name='arm_6_link'>
      <pose frame=''>0 -2.99474 0.765 0 -0 3.14158</pose>
      <inertial>
        <pose frame=''>0.040619 -0.013779 0.239465 0 -0 0</pose>
        <mass>1.42668</mass>
        <inertia>
          <ixx>0.121628</ixx>
          <ixy>0.000616705</ixy>
          <ixz>-0.0119644</ixz>
          <iyy>0.123801</iyy>
          <iyz>0.00692997</iyz>
          <izz>0.107811</izz>
        </inertia>
      </inertial>
      <collision name='arm_6_link_collision'>
        <pose frame=''>0 0 0 0 -0 0</pose>
        <geometry>
          <mesh>
            <scale>1 1 1</scale>
            <uri>model://iiwa_panda_lwa4p_ur5e/meshes/lwa4p/arm_6_link.stl</uri>
          </mesh>
        </geometry>
        <surface>
          <contact>
            <ode/>
          </contact>
          <friction>
            <ode/>
          </friction>
        </surface>
      </collision>
      <collision name='arm_6_link_fixed_joint_lump__svh_hand_base_link_collision_1'>
        <pose frame=''>0 0 0.08 0 -0 0</pose>
        <geometry>
          <mesh>
            <scale>1 1 1</scale>
            <uri>model://iiwa_panda_lwa4p_ur5e/meshes/svh/base10.dae</uri>
          </mesh>
        </geometry>
      </collision>
      <collision name='arm_6_link_fixed_joint_lump__svh_hand_e1_collision_2'>
        <pose frame=''>0 0 0.08 0 -0 0</pose>
        <geometry>
          <mesh>
            <scale>-1 1 1</scale>
            <uri>model://iiwa_panda_lwa4p_ur5e/meshes/svh/h10.dae</uri>
          </mesh>
        </geometry>
      </collision>
      <collision name='arm_6_link_fixed_joint_lump__svh_hand_virtual_k_collision_3'>
        <pose frame=''>-1e-06 -0.02634 0.190001 -3.14159 -1.57079 -1.57089</pose>
        <geometry>
          <mesh>
            <scale>1 1 1</scale>
            <uri>model://iiwa_panda_lwa4p_ur5e/meshes/svh/f20.dae</uri>
          </mesh>
        </geometry>
      </collision>
      <collision name='arm_6_link_fixed_joint_lump__svh_hand_e2_collision_4'>
        <pose frame=''>-0.0177 -0.00713 0.10748 0 -0 0</pose>
        <geometry>
          <mesh>
            <scale>-1 1 1</scale>
            <uri>model://iiwa_panda_lwa4p_ur5e/meshes/svh/h11.dae</uri>
          </mesh>
        </geometry>
      </collision>
      <visual name='arm_6_link_visual'>
        <pose frame=''>0 0 0 0 -0 0</pose>
        <geometry>
          <mesh>
            <scale>1 1 1</scale>
            <uri>model://iiwa_panda_lwa4p_ur5e/meshes/lwa4p/arm_6_link.dae</uri>
          </mesh>
        </geometry>
        <material>
          <script>
            <name>Gazebo/Grey</name>
            <uri>file://media/materials/scripts/gazebo.material</uri>
          </script>
        </material>
      </visual>
      <visual name='arm_6_link_fixed_joint_lump__svh_hand_base_link_visual_1'>
        <pose frame=''>0 0 0.08 0 -0 0</pose>
        <geometry>
          <mesh>
            <scale>1 1 1</scale>
            <uri>model://iiwa_panda_lwa4p_ur5e/meshes/svh/base10.dae</uri>
          </mesh>
        </geometry>
      </visual>
      <visual name='arm_6_link_fixed_joint_lump__svh_hand_e1_visual_2'>
        <pose frame=''>0 0 0.08 0 -0 0</pose>
        <geometry>
          <mesh>
            <scale>-1 1 1</scale>
            <uri>model://iiwa_panda_lwa4p_ur5e/meshes/svh/h10.dae</uri>
          </mesh>
        </geometry>
      </visual>
      <visual name='arm_6_link_fixed_joint_lump__svh_hand_virtual_k_visual_3'>
        <pose frame=''>-1e-06 -0.02634 0.190001 -3.14159 -1.57079 -1.57089</pose>
        <geometry>
          <mesh>
            <scale>1 1 1</scale>
            <uri>model://iiwa_panda_lwa4p_ur5e/meshes/svh/f20.dae</uri>
          </mesh>
        </geometry>
      </visual>
      <visual name='arm_6_link_fixed_joint_lump__svh_hand_e2_visual_4'>
        <pose frame=''>-0.0177 -0.00713 0.10748 0 -0 0</pose>
        <geometry>
          <mesh>
            <scale>-1 1 1</scale>
            <uri>model://iiwa_panda_lwa4p_ur5e/meshes/svh/h11.dae</uri>
          </mesh>
        </geometry>
      </visual>
      <gravity>1</gravity>
      <velocity_decay/>
      <self_collide>0</self_collide>
      <gravity>1</gravity>
    </link>
    <joint name='arm_6_joint' type='revolute'>
      <child>arm_6_link</child>
      <parent>arm_5_link</parent>
      <axis>
        <xyz>0 0 1</xyz>
        <limit>
          <lower>-2.947</lower>
          <upper>2.947</upper>
          <effort>20.1</effort>
          <velocity>1.25</velocity>
        </limit>
        <dynamics>
          <spring_reference>0</spring_reference>
          <spring_stiffness>0</spring_stiffness>
        </dynamics>
        <use_parent_model_frame>1</use_parent_model_frame>
      </axis>
    </joint>
    <link name='svh_hand_z'>
      <pose frame=''>-0.0169 -3.00787 0.845 -0 0.2618 -1.5706</pose>
      <inertial>
        <pose frame=''>0 0.001783 0.162822 0 -0 0</pose>
        <mass>0.0839</mass>
        <inertia>
          <ixx>0.00218508</ixx>
          <ixy>0</ixy>
          <ixz>0</ixz>
          <iyy>0.00280505</iyy>
          <iyz>3.76347e-05</iyz>
          <izz>0.00211004</izz>
        </inertia>
      </inertial>
      <collision name='svh_hand_z_collision'>
        <pose frame=''>0 0 0.02442 0 -0 0</pose>
        <geometry>
          <mesh>
            <scale>1 -1 1</scale>
            <uri>model://iiwa_panda_lwa4p_ur5e/meshes/svh/d10.dae</uri>
          </mesh>
        </geometry>
      </collision>
      <visual name='svh_hand_z_visual'>
        <pose frame=''>0 0 0.02442 0 -0 0</pose>
        <geometry>
          <mesh>
            <scale>1 -1 1</scale>
            <uri>model://iiwa_panda_lwa4p_ur5e/meshes/svh/d10.dae</uri>
          </mesh>
        </geometry>
      </visual>
    </link>
    <joint name='svh_hand_Thumb_Opposition' type='revolute'>
      <child>svh_hand_z</child>
      <parent>arm_6_link</parent>
      <axis>
        <xyz>5.1e-05 -0.25882 0.965926</xyz>
        <limit>
          <lower>0</lower>
          <upper>0.9879</upper>
          <effort>1000</effort>
          <velocity>1</velocity>
        </limit>
        <dynamics>
          <spring_reference>0</spring_reference>
          <spring_stiffness>0</spring_stiffness>
        </dynamics>
        <use_parent_model_frame>1</use_parent_model_frame>
      </axis>
    </joint>
    <link name='svh_hand_a'>
      <pose frame=''>-0.016898 -3.01976 0.889394 -1.88468 -0.577261 -2.96605</pose>
      <inertial>
        <pose frame=''>0.240205 0.010733 0.00019 0 -0 0</pose>
        <mass>0.41222</mass>
        <inertia>
          <ixx>0.00413</ixx>
          <ixy>0.00073</ixy>
          <ixz>-0</ixz>
          <iyy>0.01679</iyy>
          <iyz>0</iyz>
          <izz>0.01796</izz>
        </inertia>
      </inertial>
      <collision name='svh_hand_a_collision'>
        <pose frame=''>0 0 0 0 -0 0</pose>
        <geometry>
          <mesh>
            <scale>1 -1 -1</scale>
            <uri>model://iiwa_panda_lwa4p_ur5e/meshes/svh/d11.dae</uri>
          </mesh>
        </geometry>
      </collision>
      <visual name='svh_hand_a_visual'>
        <pose frame=''>0 0 0 0 -0 0</pose>
        <geometry>
          <mesh>
            <scale>1 -1 -1</scale>
            <uri>model://iiwa_panda_lwa4p_ur5e/meshes/svh/d11.dae</uri>
          </mesh>
        </geometry>
      </visual>
    </link>
    <joint name='svh_hand_Thumb_Flexion' type='revolute'>
      <child>svh_hand_a</child>
      <parent>svh_hand_z</parent>
      <axis>
        <xyz>-0.000196 0.965951 0.258727</xyz>
        <limit>
          <lower>0</lower>
          <upper>0.9704</upper>
          <effort>1000</effort>
          <velocity>1</velocity>
        </limit>
        <dynamics>
          <spring_reference>0</spring_reference>
          <spring_stiffness>0</spring_stiffness>
        </dynamics>
        <use_parent_model_frame>1</use_parent_model_frame>
      </axis>
    </joint>
    <link name='svh_hand_b'>
      <pose frame=''>-0.056914 -3.02686 0.915862 -1.88468 -0.577261 -2.96605</pose>
      <inertial>
        <pose frame=''>0.123157 -0.008382 -2.7e-05 0 -0 0</pose>
        <mass>0.08224</mass>
        <inertia>
          <ixx>0.00089</ixx>
          <ixy>5e-05</ixy>
          <ixz>0</ixz>
          <iyy>0.00139</iyy>
          <iyz>0</iyz>
          <izz>0.00103</izz>
        </inertia>
      </inertial>
      <collision name='svh_hand_b_collision'>
        <pose frame=''>0 0 0 0 -0 0</pose>
        <geometry>
          <mesh>
            <scale>1 -1 -1</scale>
            <uri>model://iiwa_panda_lwa4p_ur5e/meshes/svh/d12.dae</uri>
          </mesh>
        </geometry>
      </collision>
      <visual name='svh_hand_b_visual'>
        <pose frame=''>0 0 0 0 -0 0</pose>
        <geometry>
          <mesh>
            <scale>1 -1 -1</scale>
            <uri>model://iiwa_panda_lwa4p_ur5e/meshes/svh/d12.dae</uri>
          </mesh>
        </geometry>
      </visual>
    </link>
    <joint name='svh_hand_j3' type='revolute'>
      <child>svh_hand_b</child>
      <parent>svh_hand_a</parent>
      <axis>
        <xyz>-0.000196 0.965951 0.258727</xyz>
        <limit>
          <lower>0</lower>
          <upper>0.98506</upper>
          <effort>1000</effort>
          <velocity>1</velocity>
        </limit>
        <dynamics>
          <spring_reference>0</spring_reference>
          <spring_stiffness>0</spring_stiffness>
        </dynamics>
        <use_parent_model_frame>1</use_parent_model_frame>
      </axis>
    </joint>
    <link name='svh_hand_c'>
      <pose frame=''>-0.081667 -3.03125 0.932234 -1.88468 -0.577261 -2.96605</pose>
      <inertial>
        <pose frame=''>0.113729 0.01094 0 0 -0 0</pose>
        <mass>0.06198</mass>
        <inertia>
          <ixx>0.00025</ixx>
          <ixy>-0</ixy>
          <ixz>-0</ixz>
          <iyy>0.00051</iyy>
          <iyz>0</iyz>
          <izz>0.00052</izz>
        </inertia>
      </inertial>
      <collision name='svh_hand_c_collision'>
        <pose frame=''>0 0 0 0 -0 0</pose>
        <geometry>
          <mesh>
            <scale>1 -1 -1</scale>
            <uri>model://iiwa_panda_lwa4p_ur5e/meshes/svh/d13.dae</uri>
          </mesh>
        </geometry>
      </collision>
      <visual name='svh_hand_c_visual'>
        <pose frame=''>0 0 0 0 -0 0</pose>
        <geometry>
          <mesh>
            <scale>1 -1 -1</scale>
            <uri>model://iiwa_panda_lwa4p_ur5e/meshes/svh/d13.dae</uri>
          </mesh>
        </geometry>
      </visual>
    </link>
    <joint name='svh_hand_j4' type='revolute'>
      <child>svh_hand_c</child>
      <parent>svh_hand_b</parent>
      <axis>
        <xyz>-0.000196 0.965951 0.258727</xyz>
        <limit>
          <lower>0</lower>
          <upper>1.406</upper>
          <effort>1000</effort>
          <velocity>1</velocity>
        </limit>
        <dynamics>
          <spring_reference>0</spring_reference>
          <spring_stiffness>0</spring_stiffness>
        </dynamics>
        <use_parent_model_frame>1</use_parent_model_frame>
      </axis>
    </joint>
    <link name='svh_hand_virtual_l'>
      <pose frame=''>-0.025 -2.98161 0.955 -0 -1.5707 -1.5709</pose>
      <inertial>
        <pose frame=''>0.003634 0.000206 -0.09885 0 -0 0</pose>
        <mass>0.02383</mass>
        <inertia>
          <ixx>0.00021</ixx>
          <ixy>-0</ixy>
          <ixz>-1e-05</ixz>
          <iyy>0.00011</iyy>
          <iyz>-0</iyz>
          <izz>0.00019</izz>
        </inertia>
      </inertial>
      <collision name='svh_hand_virtual_l_collision'>
        <pose frame=''>0 0 0.01321 0 -0 0</pose>
        <geometry>
          <mesh>
            <scale>1 1 1</scale>
            <uri>model://iiwa_panda_lwa4p_ur5e/meshes/svh/f10.dae</uri>
          </mesh>
        </geometry>
      </collision>
      <visual name='svh_hand_virtual_l_visual'>
        <pose frame=''>0 0 0.01321 0 -0 0</pose>
        <geometry>
          <mesh>
            <scale>1 1 1</scale>
            <uri>model://iiwa_panda_lwa4p_ur5e/meshes/svh/f10.dae</uri>
          </mesh>
        </geometry>
      </visual>
    </link>
    <joint name='svh_hand_index_spread' type='revolute'>
      <child>svh_hand_virtual_l</child>
      <parent>arm_6_link</parent>
      <axis>
        <xyz>-0.000104 -1 -9.6e-05</xyz>
        <limit>
          <lower>0</lower>
          <upper>0.28833</upper>
          <effort>1000</effort>
          <velocity>1</velocity>
        </limit>
        <dynamics>
          <spring_reference>0</spring_reference>
          <spring_stiffness>0</spring_stiffness>
        </dynamics>
        <use_parent_model_frame>1</use_parent_model_frame>
      </axis>
    </joint>
    <link name='svh_hand_l'>
      <pose frame=''>-0.025 -2.98161 0.955 -1.5707 -1.5707 -1.5709</pose>
      <inertial>
        <pose frame=''>0.261673 0.003521 0 0 -0 0</pose>
        <mass>0.13003</mass>
        <inertia>
          <ixx>0.00051</ixx>
          <ixy>-3e-05</ixy>
          <ixz>0</ixz>
          <iyy>0.00335</iyy>
          <iyz>-0</iyz>
          <izz>0.00344</izz>
        </inertia>
      </inertial>
      <collision name='svh_hand_l_collision'>
        <pose frame=''>0 0 0 0 -0 0</pose>
        <geometry>
          <mesh>
            <scale>1 1 1</scale>
            <uri>model://iiwa_panda_lwa4p_ur5e/meshes/svh/f11.dae</uri>
          </mesh>
        </geometry>
      </collision>
      <visual name='svh_hand_l_visual'>
        <pose frame=''>0 0 0 0 -0 0</pose>
        <geometry>
          <mesh>
            <scale>1 1 1</scale>
            <uri>model://iiwa_panda_lwa4p_ur5e/meshes/svh/f11.dae</uri>
          </mesh>
        </geometry>
      </visual>
    </link>
    <joint name='svh_hand_Index_Finger_Proximal' type='revolute'>
      <child>svh_hand_l</child>
      <parent>svh_hand_virtual_l</parent>
      <axis>
        <xyz>1 -8e-06 0</xyz>
        <limit>
          <lower>0</lower>
          <upper>0.79849</upper>
          <effort>1000</effort>
          <velocity>1</velocity>
        </limit>
        <dynamics>
          <spring_reference>0</spring_reference>
          <spring_stiffness>0</spring_stiffness>
        </dynamics>
        <use_parent_model_frame>1</use_parent_model_frame>
      </axis>
    </joint>
    <link name='svh_hand_p'>
      <pose frame=''>-0.025 -2.98161 1.00304 -1.5707 -1.5707 -1.5709</pose>
      <inertial>
        <pose frame=''>0.1384 -0.004609 0 0 -0 0</pose>
        <mass>0.03264</mass>
        <inertia>
          <ixx>0.00016</ixx>
          <ixy>-0</ixy>
          <ixz>0</ixz>
          <iyy>0.00031</iyy>
          <iyz>-0</iyz>
          <izz>0.00024</izz>
        </inertia>
      </inertial>
      <collision name='svh_hand_p_collision'>
        <pose frame=''>0 0 0 0 -0 0</pose>
        <geometry>
          <mesh>
            <scale>1 1 1</scale>
            <uri>model://iiwa_panda_lwa4p_ur5e/meshes/svh/f12.dae</uri>
          </mesh>
        </geometry>
      </collision>
      <visual name='svh_hand_p_visual'>
        <pose frame=''>0 0 0 0 -0 0</pose>
        <geometry>
          <mesh>
            <scale>1 1 1</scale>
            <uri>model://iiwa_panda_lwa4p_ur5e/meshes/svh/f12.dae</uri>
          </mesh>
        </geometry>
      </visual>
    </link>
    <joint name='svh_hand_Index_Finger_Distal' type='revolute'>
      <child>svh_hand_p</child>
      <parent>svh_hand_l</parent>
      <axis>
        <xyz>1 -8e-06 0</xyz>
        <limit>
          <lower>0</lower>
          <upper>1.334</upper>
          <effort>1000</effort>
          <velocity>1</velocity>
        </limit>
        <dynamics>
          <spring_reference>0</spring_reference>
          <spring_stiffness>0</spring_stiffness>
        </dynamics>
        <use_parent_model_frame>1</use_parent_model_frame>
      </axis>
    </joint>
    <link name='svh_hand_t'>
      <pose frame=''>-0.025 -2.98162 1.02904 -1.5707 -1.5707 -1.5709</pose>
      <inertial>
        <pose frame=''>0.102924 0.000592 0 0 -0 0</pose>
        <mass>0.0324</mass>
        <inertia>
          <ixx>9e-05</ixx>
          <ixy>-1e-05</ixy>
          <ixz>-0</ixz>
          <iyy>0.00017</iyy>
          <iyz>0</iyz>
          <izz>0.00017</izz>
        </inertia>
      </inertial>
      <collision name='svh_hand_t_collision'>
        <pose frame=''>0 0 0 0 -0 0</pose>
        <geometry>
          <mesh>
            <scale>1 1 1</scale>
            <uri>model://iiwa_panda_lwa4p_ur5e/meshes/svh/f13.dae</uri>
          </mesh>
        </geometry>
      </collision>
      <visual name='svh_hand_t_visual'>
        <pose frame=''>0 0 0 0 -0 0</pose>
        <geometry>
          <mesh>
            <scale>1 1 1</scale>
            <uri>model://iiwa_panda_lwa4p_ur5e/meshes/svh/f13.dae</uri>
          </mesh>
        </geometry>
      </visual>
    </link>
    <joint name='svh_hand_j14' type='revolute'>
      <child>svh_hand_t</child>
      <parent>svh_hand_p</parent>
      <axis>
        <xyz>1 -8e-06 0</xyz>
        <limit>
          <lower>0</lower>
          <upper>1.394</upper>
          <effort>1000</effort>
          <velocity>1</velocity>
        </limit>
        <dynamics>
          <spring_reference>0</spring_reference>
          <spring_stiffness>0</spring_stiffness>
        </dynamics>
        <use_parent_model_frame>1</use_parent_model_frame>
      </axis>
    </joint>
    <link name='svh_hand_k'>
      <pose frame=''>0 -2.98161 0.955 -1.5707 -1.5707 -1.5709</pose>
      <inertial>
        <pose frame=''>0.271122 0.00413 0 0 -0 0</pose>
        <mass>0.13474</mass>
        <inertia>
          <ixx>0.00052</ixx>
          <ixy>-3e-05</ixy>
          <ixz>-0</ixz>
          <iyy>0.0037</iyy>
          <iyz>-0</iyz>
          <izz>0.0038</izz>
        </inertia>
      </inertial>
      <collision name='svh_hand_k_collision'>
        <pose frame=''>0 0 0 0 -0 0</pose>
        <geometry>
          <mesh>
            <scale>1 1 1</scale>
            <uri>model://iiwa_panda_lwa4p_ur5e/meshes/svh/f21.dae</uri>
          </mesh>
        </geometry>
      </collision>
      <visual name='svh_hand_k_visual'>
        <pose frame=''>0 0 0 0 -0 0</pose>
        <geometry>
          <mesh>
            <scale>1 1 1</scale>
            <uri>model://iiwa_panda_lwa4p_ur5e/meshes/svh/f21.dae</uri>
          </mesh>
        </geometry>
      </visual>
    </link>
    <joint name='svh_hand_Middle_Finger_Proximal' type='revolute'>
      <child>svh_hand_k</child>
      <parent>arm_6_link</parent>
      <axis>
        <xyz>1 -8e-06 0</xyz>
        <limit>
          <lower>0</lower>
          <upper>0.79849</upper>
          <effort>1000</effort>
          <velocity>1</velocity>
        </limit>
        <dynamics>
          <spring_reference>0</spring_reference>
          <spring_stiffness>0</spring_stiffness>
        </dynamics>
        <use_parent_model_frame>1</use_parent_model_frame>
      </axis>
    </joint>
    <link name='svh_hand_o'>
      <pose frame=''>0 -2.98161 1.00504 -1.5707 -1.5707 -1.5709</pose>
      <inertial>
        <pose frame=''>0.16683 -0.003774 0 0 -0 0</pose>
        <mass>0.0422</mass>
        <inertia>
          <ixx>0.0002</ixx>
          <ixy>0</ixy>
          <ixz>-0</ixz>
          <iyy>0.00047</iyy>
          <iyz>0</iyz>
          <izz>0.0004</izz>
        </inertia>
      </inertial>
      <collision name='svh_hand_o_collision'>
        <pose frame=''>0 0 0 0 -0 0</pose>
        <geometry>
          <mesh>
            <scale>1 1 1</scale>
            <uri>model://iiwa_panda_lwa4p_ur5e/meshes/svh/f22.dae</uri>
          </mesh>
        </geometry>
      </collision>
      <visual name='svh_hand_o_visual'>
        <pose frame=''>0 0 0 0 -0 0</pose>
        <geometry>
          <mesh>
            <scale>1 1 1</scale>
            <uri>model://iiwa_panda_lwa4p_ur5e/meshes/svh/f22.dae</uri>
          </mesh>
        </geometry>
      </visual>
    </link>
    <joint name='svh_hand_Middle_Finger_Distal' type='revolute'>
      <child>svh_hand_o</child>
      <parent>svh_hand_k</parent>
      <axis>
        <xyz>1 -8e-06 0</xyz>
        <limit>
          <lower>0</lower>
          <upper>1.334</upper>
          <effort>1000</effort>
          <velocity>1</velocity>
        </limit>
        <dynamics>
          <spring_reference>0</spring_reference>
          <spring_stiffness>0</spring_stiffness>
        </dynamics>
        <use_parent_model_frame>1</use_parent_model_frame>
      </axis>
    </joint>
    <link name='svh_hand_s'>
      <pose frame=''>0 -2.98162 1.03704 -1.5707 -1.5707 -1.5709</pose>
      <inertial>
        <pose frame=''>0.102794 0.00042 0 0 -0 0</pose>
        <mass>0.03239</mass>
        <inertia>
          <ixx>9e-05</ixx>
          <ixy>-1e-05</ixy>
          <ixz>0</ixz>
          <iyy>0.00017</iyy>
          <iyz>0</iyz>
          <izz>0.00017</izz>
        </inertia>
      </inertial>
      <collision name='svh_hand_s_collision'>
        <pose frame=''>0 0 0 0 -0 0</pose>
        <geometry>
          <mesh>
            <scale>1 1 1</scale>
            <uri>model://iiwa_panda_lwa4p_ur5e/meshes/svh/f23.dae</uri>
          </mesh>
        </geometry>
      </collision>
      <visual name='svh_hand_s_visual'>
        <pose frame=''>0 0 0 0 -0 0</pose>
        <geometry>
          <mesh>
            <scale>1 1 1</scale>
            <uri>model://iiwa_panda_lwa4p_ur5e/meshes/svh/f23.dae</uri>
          </mesh>
        </geometry>
      </visual>
    </link>
    <joint name='svh_hand_j15' type='revolute'>
      <child>svh_hand_s</child>
      <parent>svh_hand_o</parent>
      <axis>
        <xyz>1 -8e-06 0</xyz>
        <limit>
          <lower>0</lower>
          <upper>1.334</upper>
          <effort>1000</effort>
          <velocity>1</velocity>
        </limit>
        <dynamics>
          <spring_reference>0</spring_reference>
          <spring_stiffness>0</spring_stiffness>
        </dynamics>
        <use_parent_model_frame>1</use_parent_model_frame>
      </axis>
    </joint>
    <link name='svh_hand_virtual_i'>
      <pose frame=''>0.043755 -2.98161 0.9385 -1.5707 -1.5707 3.14158</pose>
      <inertial>
        <pose frame=''>0.003653 4.4e-05 0.100085 0 -0 0</pose>
        <mass>0.02377</mass>
        <inertia>
          <ixx>0.00021</ixx>
          <ixy>0</ixy>
          <ixz>1e-05</ixz>
          <iyy>0.00011</iyy>
          <iyz>-0</iyz>
          <izz>0.00019</izz>
        </inertia>
      </inertial>
      <collision name='svh_hand_virtual_i_collision'>
        <pose frame=''>0 0 -0.01321 0 -0 0</pose>
        <geometry>
          <mesh>
            <scale>1 1 1</scale>
            <uri>model://iiwa_panda_lwa4p_ur5e/meshes/svh/f40.dae</uri>
          </mesh>
        </geometry>
      </collision>
      <visual name='svh_hand_virtual_i_visual'>
        <pose frame=''>0 0 -0.01321 0 -0 0</pose>
        <geometry>
          <mesh>
            <scale>1 1 1</scale>
            <uri>model://iiwa_panda_lwa4p_ur5e/meshes/svh/f40.dae</uri>
          </mesh>
        </geometry>
      </visual>
    </link>
    <joint name='svh_hand_Finger_Spread' type='revolute'>
      <child>svh_hand_virtual_i</child>
      <parent>arm_6_link</parent>
      <axis>
        <xyz>-8.8e-05 1 -0</xyz>
        <limit>
          <lower>0</lower>
          <upper>0.5829</upper>
          <effort>1000</effort>
          <velocity>1</velocity>
        </limit>
        <dynamics>
          <spring_reference>0</spring_reference>
          <spring_stiffness>0</spring_stiffness>
        </dynamics>
        <use_parent_model_frame>1</use_parent_model_frame>
      </axis>
    </joint>
    <link name='svh_hand_i'>
      <pose frame=''>0.043755 -2.98161 0.9385 0 -1.5707 3.14158</pose>
      <inertial>
        <pose frame=''>0.232293 0.00622 0 0 -0 0</pose>
        <mass>0.12544</mass>
        <inertia>
          <ixx>0.00049</ixx>
          <ixy>6e-05</ixy>
          <ixz>-0</ixz>
          <iyy>0.00316</iyy>
          <iyz>0</iyz>
          <izz>0.00328</izz>
        </inertia>
      </inertial>
      <collision name='svh_hand_i_collision'>
        <pose frame=''>0 0 0 0 -0 0</pose>
        <geometry>
          <mesh>
            <scale>1 1 1</scale>
            <uri>model://iiwa_panda_lwa4p_ur5e/meshes/svh/f41.dae</uri>
          </mesh>
        </geometry>
      </collision>
      <visual name='svh_hand_i_visual'>
        <pose frame=''>0 0 0 0 -0 0</pose>
        <geometry>
          <mesh>
            <scale>1 1 1</scale>
            <uri>model://iiwa_panda_lwa4p_ur5e/meshes/svh/f41.dae</uri>
          </mesh>
        </geometry>
      </visual>
    </link>
    <joint name='svh_hand_Pinky' type='revolute'>
      <child>svh_hand_i</child>
      <parent>svh_hand_virtual_i</parent>
      <axis>
        <xyz>1 -8e-06 9.6e-05</xyz>
        <limit>
          <lower>0</lower>
          <upper>0.98175</upper>
          <effort>1000</effort>
          <velocity>1</velocity>
        </limit>
        <dynamics>
          <spring_reference>0</spring_reference>
          <spring_stiffness>0</spring_stiffness>
        </dynamics>
        <use_parent_model_frame>1</use_parent_model_frame>
      </axis>
    </joint>
    <link name='svh_hand_m'>
      <pose frame=''>0.043751 -2.98161 0.98304 0 -1.5707 3.14158</pose>
      <inertial>
        <pose frame=''>0.119665 -0.009328 0 0 -0 0</pose>
        <mass>0.02488</mass>
        <inertia>
          <ixx>0.00013</ixx>
          <ixy>-0</ixy>
          <ixz>-0</ixz>
          <iyy>0.00023</iyy>
          <iyz>0</iyz>
          <izz>0.00016</izz>
        </inertia>
      </inertial>
      <collision name='svh_hand_m_collision'>
        <pose frame=''>0 0 0 0 -0 0</pose>
        <geometry>
          <mesh>
            <scale>1 1 1</scale>
            <uri>model://iiwa_panda_lwa4p_ur5e/meshes/svh/f42.dae</uri>
          </mesh>
        </geometry>
      </collision>
      <visual name='svh_hand_m_visual'>
        <pose frame=''>0 0 0 0 -0 0</pose>
        <geometry>
          <mesh>
            <scale>1 1 1</scale>
            <uri>model://iiwa_panda_lwa4p_ur5e/meshes/svh/f42.dae</uri>
          </mesh>
        </geometry>
      </visual>
    </link>
    <joint name='svh_hand_j13' type='revolute'>
      <child>svh_hand_m</child>
      <parent>svh_hand_i</parent>
      <axis>
        <xyz>1 -8e-06 9.6e-05</xyz>
        <limit>
          <lower>0</lower>
          <upper>1.334</upper>
          <effort>1000</effort>
          <velocity>1</velocity>
        </limit>
        <dynamics>
          <spring_reference>0</spring_reference>
          <spring_stiffness>0</spring_stiffness>
        </dynamics>
        <use_parent_model_frame>1</use_parent_model_frame>
      </axis>
    </joint>
    <link name='svh_hand_q'>
      <pose frame=''>0.043749 -2.98161 1.00504 0 -1.5707 3.14158</pose>
      <inertial>
        <pose frame=''>0.102896 0.000307 0 0 -0 0</pose>
        <mass>0.03234</mass>
        <inertia>
          <ixx>9e-05</ixx>
          <ixy>-1e-05</ixy>
          <ixz>-0</ixz>
          <iyy>0.00017</iyy>
          <iyz>0</iyz>
          <izz>0.00017</izz>
        </inertia>
      </inertial>
      <collision name='svh_hand_q_collision'>
        <pose frame=''>0 0 0 0 -0 0</pose>
        <geometry>
          <mesh>
            <scale>1 1 1</scale>
            <uri>model://iiwa_panda_lwa4p_ur5e/meshes/svh/f43.dae</uri>
          </mesh>
        </geometry>
      </collision>
      <visual name='svh_hand_q_visual'>
        <pose frame=''>0 0 0 0 -0 0</pose>
        <geometry>
          <mesh>
            <scale>1 1 1</scale>
            <uri>model://iiwa_panda_lwa4p_ur5e/meshes/svh/f43.dae</uri>
          </mesh>
        </geometry>
      </visual>
    </link>
    <joint name='svh_hand_j17' type='revolute'>
      <child>svh_hand_q</child>
      <parent>svh_hand_m</parent>
      <axis>
        <xyz>1 -8e-06 9.6e-05</xyz>
        <limit>
          <lower>0</lower>
          <upper>1.3971</upper>
          <effort>1000</effort>
          <velocity>1</velocity>
        </limit>
        <dynamics>
          <spring_reference>0</spring_reference>
          <spring_stiffness>0</spring_stiffness>
        </dynamics>
        <use_parent_model_frame>1</use_parent_model_frame>
      </axis>
    </joint>
    <link name='svh_hand_virtual_j'>
      <pose frame=''>0.022255 -2.98161 0.948 -1.5707 -1.5707 3.14158</pose>
      <inertial>
        <pose frame=''>0.003805 0.000386 0.100079 0 -0 0</pose>
        <mass>0.02377</mass>
        <inertia>
          <ixx>0.00021</ixx>
          <ixy>0</ixy>
          <ixz>1e-05</ixz>
          <iyy>0.00011</iyy>
          <iyz>-0</iyz>
          <izz>0.00019</izz>
        </inertia>
      </inertial>
      <collision name='svh_hand_virtual_j_collision'>
        <pose frame=''>0 0 -0.01321 0 -0 0</pose>
        <geometry>
          <mesh>
            <scale>1 1 1</scale>
            <uri>model://iiwa_panda_lwa4p_ur5e/meshes/svh/f30.dae</uri>
          </mesh>
        </geometry>
      </collision>
      <visual name='svh_hand_virtual_j_visual'>
        <pose frame=''>0 0 -0.01321 0 -0 0</pose>
        <geometry>
          <mesh>
            <scale>1 1 1</scale>
            <uri>model://iiwa_panda_lwa4p_ur5e/meshes/svh/f30.dae</uri>
          </mesh>
        </geometry>
      </visual>
    </link>
    <joint name='svh_hand_ring_spread' type='revolute'>
      <child>svh_hand_virtual_j</child>
      <parent>arm_6_link</parent>
      <axis>
        <xyz>-8.8e-05 1 -0</xyz>
        <limit>
          <lower>0</lower>
          <upper>0.28833</upper>
          <effort>1000</effort>
          <velocity>1</velocity>
        </limit>
        <dynamics>
          <spring_reference>0</spring_reference>
          <spring_stiffness>0</spring_stiffness>
        </dynamics>
        <use_parent_model_frame>1</use_parent_model_frame>
      </axis>
    </joint>
    <link name='svh_hand_j'>
      <pose frame=''>0.022255 -2.98161 0.948 0 -1.5707 3.14158</pose>
      <inertial>
        <pose frame=''>0.258283 -0.00154 0 0 -0 0</pose>
        <mass>0.1377</mass>
        <inertia>
          <ixx>0.00055</ixx>
          <ixy>0.00018</ixy>
          <ixz>-0</ixz>
          <iyy>0.00411</iyy>
          <iyz>0</iyz>
          <izz>0.00426</izz>
        </inertia>
      </inertial>
      <collision name='svh_hand_j_collision'>
        <pose frame=''>0 0 0 0 -0 0</pose>
        <geometry>
          <mesh>
            <scale>1 1 1</scale>
            <uri>model://iiwa_panda_lwa4p_ur5e/meshes/svh/f31.dae</uri>
          </mesh>
        </geometry>
      </collision>
      <visual name='svh_hand_j_visual'>
        <pose frame=''>0 0 0 0 -0 0</pose>
        <geometry>
          <mesh>
            <scale>1 1 1</scale>
            <uri>model://iiwa_panda_lwa4p_ur5e/meshes/svh/f31.dae</uri>
          </mesh>
        </geometry>
      </visual>
    </link>
    <joint name='svh_hand_Ring_Finger' type='revolute'>
      <child>svh_hand_j</child>
      <parent>svh_hand_virtual_j</parent>
      <axis>
        <xyz>1 -8e-06 9.6e-05</xyz>
        <limit>
          <lower>0</lower>
          <upper>0.98175</upper>
          <effort>1000</effort>
          <velocity>1</velocity>
        </limit>
        <dynamics>
          <spring_reference>0</spring_reference>
          <spring_stiffness>0</spring_stiffness>
        </dynamics>
        <use_parent_model_frame>1</use_parent_model_frame>
      </axis>
    </joint>
    <link name='svh_hand_n'>
      <pose frame=''>0.02225 -2.98161 0.99804 0 -1.5707 3.14158</pose>
      <inertial>
        <pose frame=''>0.166851 -0.00362 0 0 -0 0</pose>
        <mass>0.04207</mass>
        <inertia>
          <ixx>0.00019</ixx>
          <ixy>0</ixy>
          <ixz>-0</ixz>
          <iyy>0.00047</iyy>
          <iyz>0</iyz>
          <izz>0.0004</izz>
        </inertia>
      </inertial>
      <collision name='svh_hand_n_collision'>
        <pose frame=''>0 0 0 0 -0 0</pose>
        <geometry>
          <mesh>
            <scale>1 1 1</scale>
            <uri>model://iiwa_panda_lwa4p_ur5e/meshes/svh/f32.dae</uri>
          </mesh>
        </geometry>
      </collision>
      <visual name='svh_hand_n_visual'>
        <pose frame=''>0 0 0 0 -0 0</pose>
        <geometry>
          <mesh>
            <scale>1 1 1</scale>
            <uri>model://iiwa_panda_lwa4p_ur5e/meshes/svh/f32.dae</uri>
          </mesh>
        </geometry>
      </visual>
    </link>
    <joint name='svh_hand_j12' type='revolute'>
      <child>svh_hand_n</child>
      <parent>svh_hand_j</parent>
      <axis>
        <xyz>1 -8e-06 9.6e-05</xyz>
        <limit>
          <lower>0</lower>
          <upper>1.334</upper>
          <effort>1000</effort>
          <velocity>1</velocity>
        </limit>
        <dynamics>
          <spring_reference>0</spring_reference>
          <spring_stiffness>0</spring_stiffness>
        </dynamics>
        <use_parent_model_frame>1</use_parent_model_frame>
      </axis>
    </joint>
    <link name='svh_hand_r'>
      <pose frame=''>0.022247 -2.98161 1.03004 0 -1.5707 3.14158</pose>
      <inertial>
        <pose frame=''>0.102676 0.000301 0 0 -0 0</pose>
        <mass>0.03229</mass>
        <inertia>
          <ixx>9e-05</ixx>
          <ixy>-1e-05</ixy>
          <ixz>0</ixz>
          <iyy>0.00017</iyy>
          <iyz>-0</iyz>
          <izz>0.00017</izz>
        </inertia>
      </inertial>
      <collision name='svh_hand_r_collision'>
        <pose frame=''>0 0 0 0 -0 0</pose>
        <geometry>
          <mesh>
            <scale>1 1 1</scale>
            <uri>model://iiwa_panda_lwa4p_ur5e/meshes/svh/f33.dae</uri>
          </mesh>
        </geometry>
      </collision>
      <visual name='svh_hand_r_visual'>
        <pose frame=''>0 0 0 0 -0 0</pose>
        <geometry>
          <mesh>
            <scale>1 1 1</scale>
            <uri>model://iiwa_panda_lwa4p_ur5e/meshes/svh/f33.dae</uri>
          </mesh>
        </geometry>
      </visual>
    </link>
    <joint name='svh_hand_j16' type='revolute'>
      <child>svh_hand_r</child>
      <parent>svh_hand_n</parent>
      <axis>
        <xyz>1 -8e-06 9.6e-05</xyz>
        <limit>
          <lower>0</lower>
          <upper>1.395</upper>
          <effort>1000</effort>
          <velocity>1</velocity>
        </limit>
        <dynamics>
          <spring_reference>0</spring_reference>
          <spring_stiffness>0</spring_stiffness>
        </dynamics>
        <use_parent_model_frame>1</use_parent_model_frame>
      </axis>
    </joint>
    <link name='panda_link0'>
      <pose frame=''>0 -5 0 0 -0 0</pose>
      <inertial>
        <pose frame=''>0 0 0 0 -0 0</pose>
        <mass>3.06</mass>
        <inertia>
          <ixx>0.3</ixx>
          <ixy>0</ixy>
          <ixz>0</ixz>
          <iyy>0.3</iyy>
          <iyz>0</iyz>
          <izz>0.3</izz>
        </inertia>
      </inertial>
      <collision name='panda_link0_collision'>
        <pose frame=''>0 0 0 0 -0 0</pose>
        <geometry>
          <mesh>
            <scale>1 1 1</scale>
            <uri>model://iiwa_panda_lwa4p_ur5e/meshes/panda/collision/link0.stl</uri>
          </mesh>
        </geometry>
        <surface>
          <contact>
            <ode/>
          </contact>
          <friction>
            <ode>
              <mu>0.2</mu>
              <mu2>0.2</mu2>
            </ode>
          </friction>
        </surface>
      </collision>
      <visual name='panda_link0_visual'>
        <pose frame=''>0 0 0 0 -0 0</pose>
        <geometry>
          <mesh>
            <scale>1 1 1</scale>
            <uri>model://iiwa_panda_lwa4p_ur5e/meshes/panda/visual/link0.dae</uri>
          </mesh>
        </geometry>
        <material>
          <script>
            <name>Gazebo/White</name>
            <uri>file://media/materials/scripts/gazebo.material</uri>
          </script>
        </material>
      </visual>
      <gravity>1</gravity>
      <velocity_decay/>
    </link>
    <joint name='panda_joint_world' type='fixed'>
      <child>panda_link0</child>
      <parent>world</parent>
    </joint>
    <link name='panda_link1'>
      <pose frame=''>0 -5 0.333 0 -0 0</pose>
      <inertial>
        <pose frame=''>0 0 0 0 -0 0</pose>
        <mass>2.34</mass>
        <inertia>
          <ixx>0.3</ixx>
          <ixy>0</ixy>
          <ixz>0</ixz>
          <iyy>0.3</iyy>
          <iyz>0</iyz>
          <izz>0.3</izz>
        </inertia>
      </inertial>
      <collision name='panda_link1_collision'>
        <pose frame=''>0 0 0 0 -0 0</pose>
        <geometry>
          <mesh>
            <scale>1 1 1</scale>
            <uri>model://iiwa_panda_lwa4p_ur5e/meshes/panda/collision/link1.stl</uri>
          </mesh>
        </geometry>
        <surface>
          <contact>
            <ode/>
          </contact>
          <friction>
            <ode>
              <mu>0.2</mu>
              <mu2>0.2</mu2>
            </ode>
          </friction>
        </surface>
      </collision>
      <visual name='panda_link1_visual'>
        <pose frame=''>0 0 0 0 -0 0</pose>
        <geometry>
          <mesh>
            <scale>1 1 1</scale>
            <uri>model://iiwa_panda_lwa4p_ur5e/meshes/panda/visual/link1.dae</uri>
          </mesh>
        </geometry>
        <material>
          <script>
            <name>Gazebo/White</name>
            <uri>file://media/materials/scripts/gazebo.material</uri>
          </script>
        </material>
      </visual>
      <gravity>1</gravity>
      <velocity_decay/>
    </link>
    <joint name='panda_joint1' type='revolute'>
      <child>panda_link1</child>
      <parent>panda_link0</parent>
      <axis>
        <xyz>0 0 1</xyz>
        <limit>
          <lower>-2.8973</lower>
          <upper>2.8973</upper>
          <effort>87</effort>
          <velocity>2.175</velocity>
        </limit>
        <dynamics>
          <spring_reference>0</spring_reference>
          <spring_stiffness>0</spring_stiffness>
        </dynamics>
        <use_parent_model_frame>1</use_parent_model_frame>
      </axis>
    </joint>
    <link name='panda_link2'>
      <pose frame=''>0 -5 0.333 -1.5708 0 0</pose>
      <inertial>
        <pose frame=''>0 0 0 0 -0 0</pose>
        <mass>2.36</mass>
        <inertia>
          <ixx>0.3</ixx>
          <ixy>0</ixy>
          <ixz>0</ixz>
          <iyy>0.3</iyy>
          <iyz>0</iyz>
          <izz>0.3</izz>
        </inertia>
      </inertial>
      <collision name='panda_link2_collision'>
        <pose frame=''>0 0 0 0 -0 0</pose>
        <geometry>
          <cylinder>
            <length>0.12</length>
            <radius>0.06</radius>
          </cylinder>
        </geometry>
        <surface>
          <contact>
            <ode/>
          </contact>
          <friction>
            <ode>
              <mu>0.2</mu>
              <mu2>0.2</mu2>
            </ode>
          </friction>
        </surface>
      </collision>
      <collision name='panda_link2_collision_1'>
        <pose frame=''>0 0 -0.06 0 -0 0</pose>
        <geometry>
          <sphere>
            <radius>0.06</radius>
          </sphere>
        </geometry>
        <surface>
          <contact>
            <ode/>
          </contact>
          <friction>
            <ode>
              <mu>0.2</mu>
              <mu2>0.2</mu2>
            </ode>
          </friction>
        </surface>
      </collision>
      <collision name='panda_link2_collision_2'>
        <pose frame=''>0 0 0.06 0 -0 0</pose>
        <geometry>
          <sphere>
            <radius>0.06</radius>
          </sphere>
        </geometry>
        <surface>
          <contact>
            <ode/>
          </contact>
          <friction>
            <ode>
              <mu>0.2</mu>
              <mu2>0.2</mu2>
            </ode>
          </friction>
        </surface>
      </collision>
      <visual name='panda_link2_visual'>
        <pose frame=''>0 0 0 0 -0 0</pose>
        <geometry>
          <mesh>
            <scale>1 1 1</scale>
            <uri>model://iiwa_panda_lwa4p_ur5e/meshes/panda/visual/link2.dae</uri>
          </mesh>
        </geometry>
        <material>
          <script>
            <name>Gazebo/White</name>
            <uri>file://media/materials/scripts/gazebo.material</uri>
          </script>
        </material>
      </visual>
      <gravity>1</gravity>
      <velocity_decay/>
    </link>
    <joint name='panda_joint2' type='revolute'>
      <child>panda_link2</child>
      <parent>panda_link1</parent>
      <axis>
        <xyz>0 1 0</xyz>
        <limit>
          <lower>-1.7628</lower>
          <upper>1.7628</upper>
          <effort>87</effort>
          <velocity>2.175</velocity>
        </limit>
        <dynamics>
          <spring_reference>0</spring_reference>
          <spring_stiffness>0</spring_stiffness>
        </dynamics>
        <use_parent_model_frame>1</use_parent_model_frame>
      </axis>
    </joint>
    <link name='panda_link3'>
      <pose frame=''>0 -5 0.649 0 -0 0</pose>
      <inertial>
        <pose frame=''>0 0 0 0 -0 0</pose>
        <mass>2.38</mass>
        <inertia>
          <ixx>0.3</ixx>
          <ixy>0</ixy>
          <ixz>0</ixz>
          <iyy>0.3</iyy>
          <iyz>0</iyz>
          <izz>0.3</izz>
        </inertia>
      </inertial>
      <collision name='panda_link3_collision'>
        <pose frame=''>0 0 -0.145 0 -0 0</pose>
        <geometry>
          <cylinder>
            <length>0.15</length>
            <radius>0.06</radius>
          </cylinder>
        </geometry>
        <surface>
          <contact>
            <ode/>
          </contact>
          <friction>
            <ode>
              <mu>0.2</mu>
              <mu2>0.2</mu2>
            </ode>
          </friction>
        </surface>
      </collision>
      <collision name='panda_link3_collision_1'>
        <pose frame=''>0 0 -0.22 0 -0 0</pose>
        <geometry>
          <sphere>
            <radius>0.06</radius>
          </sphere>
        </geometry>
        <surface>
          <contact>
            <ode/>
          </contact>
          <friction>
            <ode>
              <mu>0.2</mu>
              <mu2>0.2</mu2>
            </ode>
          </friction>
        </surface>
      </collision>
      <collision name='panda_link3_collision_2'>
        <pose frame=''>0 0 -0.07 0 -0 0</pose>
        <geometry>
          <sphere>
            <radius>0.06</radius>
          </sphere>
        </geometry>
        <surface>
          <contact>
            <ode/>
          </contact>
          <friction>
            <ode>
              <mu>0.2</mu>
              <mu2>0.2</mu2>
            </ode>
          </friction>
        </surface>
      </collision>
      <visual name='panda_link3_visual'>
        <pose frame=''>0 0 0 0 -0 0</pose>
        <geometry>
          <mesh>
            <scale>1 1 1</scale>
            <uri>model://iiwa_panda_lwa4p_ur5e/meshes/panda/visual/link3.dae</uri>
          </mesh>
        </geometry>
        <material>
          <script>
            <name>Gazebo/White</name>
            <uri>file://media/materials/scripts/gazebo.material</uri>
          </script>
        </material>
      </visual>
      <gravity>1</gravity>
      <velocity_decay/>
    </link>
    <joint name='panda_joint3' type='revolute'>
      <child>panda_link3</child>
      <parent>panda_link2</parent>
      <axis>
        <xyz>0 0 1</xyz>
        <limit>
          <lower>-2.8973</lower>
          <upper>2.8973</upper>
          <effort>87</effort>
          <velocity>2.175</velocity>
        </limit>
        <dynamics>
          <spring_reference>0</spring_reference>
          <spring_stiffness>0</spring_stiffness>
        </dynamics>
        <use_parent_model_frame>1</use_parent_model_frame>
      </axis>
    </joint>
    <link name='panda_link4'>
      <pose frame=''>0.0825 -5 0.649 1.5708 -0 0</pose>
      <inertial>
        <pose frame=''>0 0 0 0 -0 0</pose>
        <mass>2.43</mass>
        <inertia>
          <ixx>0.3</ixx>
          <ixy>0</ixy>
          <ixz>0</ixz>
          <iyy>0.3</iyy>
          <iyz>0</iyz>
          <izz>0.3</izz>
        </inertia>
      </inertial>
      <collision name='panda_link4_collision'>
        <pose frame=''>0 0 0 0 -0 0</pose>
        <geometry>
          <cylinder>
            <length>0.12</length>
            <radius>0.06</radius>
          </cylinder>
        </geometry>
        <surface>
          <contact>
            <ode/>
          </contact>
          <friction>
            <ode>
              <mu>0.2</mu>
              <mu2>0.2</mu2>
            </ode>
          </friction>
        </surface>
      </collision>
      <collision name='panda_link4_collision_1'>
        <pose frame=''>0 0 0.06 0 -0 0</pose>
        <geometry>
          <sphere>
            <radius>0.06</radius>
          </sphere>
        </geometry>
        <surface>
          <contact>
            <ode/>
          </contact>
          <friction>
            <ode>
              <mu>0.2</mu>
              <mu2>0.2</mu2>
            </ode>
          </friction>
        </surface>
      </collision>
      <collision name='panda_link4_collision_2'>
        <pose frame=''>0 0 -0.06 0 -0 0</pose>
        <geometry>
          <sphere>
            <radius>0.06</radius>
          </sphere>
        </geometry>
        <surface>
          <contact>
            <ode/>
          </contact>
          <friction>
            <ode>
              <mu>0.2</mu>
              <mu2>0.2</mu2>
            </ode>
          </friction>
        </surface>
      </collision>
      <visual name='panda_link4_visual'>
        <pose frame=''>0 0 0 0 -0 0</pose>
        <geometry>
          <mesh>
            <scale>1 1 1</scale>
            <uri>model://iiwa_panda_lwa4p_ur5e/meshes/panda/visual/link4.dae</uri>
          </mesh>
        </geometry>
        <material>
          <script>
            <name>Gazebo/White</name>
            <uri>file://media/materials/scripts/gazebo.material</uri>
          </script>
        </material>
      </visual>
      <gravity>1</gravity>
      <velocity_decay/>
    </link>
    <joint name='panda_joint4' type='revolute'>
      <child>panda_link4</child>
      <parent>panda_link3</parent>
      <axis>
        <xyz>0 -1 0</xyz>
        <limit>
          <lower>-3.0718</lower>
          <upper>-0.0698</upper>
          <effort>87</effort>
          <velocity>2.175</velocity>
        </limit>
        <dynamics>
          <spring_reference>0</spring_reference>
          <spring_stiffness>0</spring_stiffness>
        </dynamics>
        <use_parent_model_frame>1</use_parent_model_frame>
      </axis>
    </joint>
    <link name='panda_link5'>
      <pose frame=''>-0 -5 1.033 0 -0 0</pose>
      <inertial>
        <pose frame=''>0 0 0 0 -0 0</pose>
        <mass>3.5</mass>
        <inertia>
          <ixx>0.3</ixx>
          <ixy>0</ixy>
          <ixz>0</ixz>
          <iyy>0.3</iyy>
          <iyz>0</iyz>
          <izz>0.3</izz>
        </inertia>
      </inertial>
      <collision name='panda_link5_collision'>
        <pose frame=''>0 0 -0.26 0 -0 0</pose>
        <geometry>
          <cylinder>
            <length>0.1</length>
            <radius>0.06</radius>
          </cylinder>
        </geometry>
        <surface>
          <contact>
            <ode/>
          </contact>
          <friction>
            <ode>
              <mu>0.2</mu>
              <mu2>0.2</mu2>
            </ode>
          </friction>
        </surface>
      </collision>
      <collision name='panda_link5_collision_1'>
        <pose frame=''>0 0 -0.31 0 -0 0</pose>
        <geometry>
          <sphere>
            <radius>0.06</radius>
          </sphere>
        </geometry>
        <surface>
          <contact>
            <ode/>
          </contact>
          <friction>
            <ode>
              <mu>0.2</mu>
              <mu2>0.2</mu2>
            </ode>
          </friction>
        </surface>
      </collision>
      <collision name='panda_link5_collision_2'>
        <pose frame=''>0 0 -0.21 0 -0 0</pose>
        <geometry>
          <sphere>
            <radius>0.06</radius>
          </sphere>
        </geometry>
        <surface>
          <contact>
            <ode/>
          </contact>
          <friction>
            <ode>
              <mu>0.2</mu>
              <mu2>0.2</mu2>
            </ode>
          </friction>
        </surface>
      </collision>
      <collision name='panda_link5_collision_3'>
        <pose frame=''>0 0.08 -0.13 0 -0 0</pose>
        <geometry>
          <cylinder>
            <length>0.14</length>
            <radius>0.025</radius>
          </cylinder>
        </geometry>
        <surface>
          <contact>
            <ode/>
          </contact>
          <friction>
            <ode>
              <mu>0.2</mu>
              <mu2>0.2</mu2>
            </ode>
          </friction>
        </surface>
      </collision>
      <collision name='panda_link5_collision_4'>
        <pose frame=''>0 0.08 -0.06 0 -0 0</pose>
        <geometry>
          <sphere>
            <radius>0.025</radius>
          </sphere>
        </geometry>
        <surface>
          <contact>
            <ode/>
          </contact>
          <friction>
            <ode>
              <mu>0.2</mu>
              <mu2>0.2</mu2>
            </ode>
          </friction>
        </surface>
      </collision>
      <collision name='panda_link5_collision_5'>
        <pose frame=''>0 0.08 -0.2 0 -0 0</pose>
        <geometry>
          <sphere>
            <radius>0.025</radius>
          </sphere>
        </geometry>
        <surface>
          <contact>
            <ode/>
          </contact>
          <friction>
            <ode>
              <mu>0.2</mu>
              <mu2>0.2</mu2>
            </ode>
          </friction>
        </surface>
      </collision>
      <visual name='panda_link5_visual'>
        <pose frame=''>0 0 0 0 -0 0</pose>
        <geometry>
          <mesh>
            <scale>1 1 1</scale>
            <uri>model://iiwa_panda_lwa4p_ur5e/meshes/panda/visual/link5.dae</uri>
          </mesh>
        </geometry>
        <material>
          <script>
            <name>Gazebo/White</name>
            <uri>file://media/materials/scripts/gazebo.material</uri>
          </script>
        </material>
      </visual>
      <gravity>1</gravity>
      <velocity_decay/>
    </link>
    <joint name='panda_joint5' type='revolute'>
      <child>panda_link5</child>
      <parent>panda_link4</parent>
      <axis>
        <xyz>0 0 1</xyz>
        <limit>
          <lower>-2.8973</lower>
          <upper>2.8973</upper>
          <effort>12</effort>
          <velocity>2.61</velocity>
        </limit>
        <dynamics>
          <spring_reference>0</spring_reference>
          <spring_stiffness>0</spring_stiffness>
        </dynamics>
        <use_parent_model_frame>1</use_parent_model_frame>
      </axis>
    </joint>
    <link name='panda_link6'>
      <pose frame=''>-0 -5 1.033 1.5708 -0 0</pose>
      <inertial>
        <pose frame=''>0 0 0 0 -0 0</pose>
        <mass>1.47</mass>
        <inertia>
          <ixx>0.3</ixx>
          <ixy>0</ixy>
          <ixz>0</ixz>
          <iyy>0.3</iyy>
          <iyz>0</iyz>
          <izz>0.3</izz>
        </inertia>
      </inertial>
      <collision name='panda_link6_collision'>
        <pose frame=''>0 0 -0.03 0 -0 0</pose>
        <geometry>
          <cylinder>
            <length>0.08</length>
            <radius>0.05</radius>
          </cylinder>
        </geometry>
        <surface>
          <contact>
            <ode/>
          </contact>
          <friction>
            <ode>
              <mu>0.2</mu>
              <mu2>0.2</mu2>
            </ode>
          </friction>
        </surface>
      </collision>
      <collision name='panda_link6_collision_1'>
        <pose frame=''>0 0 0.01 0 -0 0</pose>
        <geometry>
          <sphere>
            <radius>0.05</radius>
          </sphere>
        </geometry>
        <surface>
          <contact>
            <ode/>
          </contact>
          <friction>
            <ode>
              <mu>0.2</mu>
              <mu2>0.2</mu2>
            </ode>
          </friction>
        </surface>
      </collision>
      <collision name='panda_link6_collision_2'>
        <pose frame=''>0 0 -0.07 0 -0 0</pose>
        <geometry>
          <sphere>
            <radius>0.05</radius>
          </sphere>
        </geometry>
        <surface>
          <contact>
            <ode/>
          </contact>
          <friction>
            <ode>
              <mu>0.2</mu>
              <mu2>0.2</mu2>
            </ode>
          </friction>
        </surface>
      </collision>
      <visual name='panda_link6_visual'>
        <pose frame=''>0 0 0 0 -0 0</pose>
        <geometry>
          <mesh>
            <scale>1 1 1</scale>
            <uri>model://iiwa_panda_lwa4p_ur5e/meshes/panda/visual/link6.dae</uri>
          </mesh>
        </geometry>
        <material>
          <script>
            <name>Gazebo/White</name>
            <uri>file://media/materials/scripts/gazebo.material</uri>
          </script>
        </material>
      </visual>
      <gravity>1</gravity>
      <velocity_decay/>
    </link>
    <joint name='panda_joint6' type='revolute'>
      <child>panda_link6</child>
      <parent>panda_link5</parent>
      <axis>
        <xyz>0 -1 0</xyz>
        <limit>
          <lower>-0.0175</lower>
          <upper>3.7525</upper>
          <effort>12</effort>
          <velocity>2.61</velocity>
        </limit>
        <dynamics>
          <spring_reference>0</spring_reference>
          <spring_stiffness>0</spring_stiffness>
        </dynamics>
        <use_parent_model_frame>1</use_parent_model_frame>
      </axis>
    </joint>
    <link name='panda_link7'>
      <pose frame=''>0.088 -5 1.033 3.14159 -0 0</pose>
      <inertial>
        <pose frame=''>0 0 0.076525 0 -0 0</pose>
        <mass>1.58</mass>
        <inertia>
          <ixx>0.703685</ixx>
          <ixy>0</ixy>
          <ixz>0</ixz>
          <iyy>0.703685</iyy>
          <iyz>0</iyz>
          <izz>0.7</izz>
        </inertia>
      </inertial>
      <collision name='panda_link7_collision'>
        <pose frame=''>0 0 0.01 0 -0 0</pose>
        <geometry>
          <cylinder>
            <length>0.14</length>
            <radius>0.04</radius>
          </cylinder>
        </geometry>
        <surface>
          <contact>
            <ode/>
          </contact>
          <friction>
            <ode>
              <mu>0.2</mu>
              <mu2>0.2</mu2>
            </ode>
          </friction>
        </surface>
      </collision>
      <collision name='panda_link7_collision_1'>
        <pose frame=''>0 0 0.08 0 -0 0</pose>
        <geometry>
          <sphere>
            <radius>0.04</radius>
          </sphere>
        </geometry>
        <surface>
          <contact>
            <ode/>
          </contact>
          <friction>
            <ode>
              <mu>0.2</mu>
              <mu2>0.2</mu2>
            </ode>
          </friction>
        </surface>
      </collision>
      <collision name='panda_link7_collision_2'>
        <pose frame=''>0 0 -0.06 0 -0 0</pose>
        <geometry>
          <sphere>
            <radius>0.04</radius>
          </sphere>
        </geometry>
        <surface>
          <contact>
            <ode/>
          </contact>
          <friction>
            <ode>
              <mu>0.2</mu>
              <mu2>0.2</mu2>
            </ode>
          </friction>
        </surface>
      </collision>
      <collision name='panda_link7_fixed_joint_lump__panda_hand_collision_3'>
        <pose frame=''>0 0 0.107 0 0 -0.785398</pose>
        <geometry>
          <mesh>
            <scale>1 1 1</scale>
            <uri>model://iiwa_panda_lwa4p_ur5e/meshes/panda/collision/hand.stl</uri>
          </mesh>
        </geometry>
        <surface>
          <contact>
            <ode/>
          </contact>
          <friction>
            <ode>
              <mu>0.2</mu>
              <mu2>0.2</mu2>
            </ode>
          </friction>
        </surface>
      </collision>
      <visual name='panda_link7_visual'>
        <pose frame=''>0 0 0 0 -0 0</pose>
        <geometry>
          <mesh>
            <scale>1 1 1</scale>
            <uri>model://iiwa_panda_lwa4p_ur5e/meshes/panda/visual/link7.dae</uri>
          </mesh>
        </geometry>
        <material>
          <script>
            <name>Gazebo/Grey</name>
            <uri>file://media/materials/scripts/gazebo.material</uri>
          </script>
        </material>
      </visual>
      <visual name='panda_link7_fixed_joint_lump__panda_hand_visual_1'>
        <pose frame=''>0 0 0.107 0 0 -0.785398</pose>
        <geometry>
          <mesh>
            <scale>1 1 1</scale>
            <uri>model://iiwa_panda_lwa4p_ur5e/meshes/panda/visual/hand.dae</uri>
          </mesh>
        </geometry>
        <material>
          <script>
            <name>Gazebo/Grey</name>
            <uri>file://media/materials/scripts/gazebo.material</uri>
          </script>
        </material>
      </visual>
      <velocity_decay/>
      <velocity_decay/>
      <gravity>1</gravity>
      <velocity_decay/>
    </link>
    <joint name='panda_joint7' type='revolute'>
      <child>panda_link7</child>
      <parent>panda_link6</parent>
      <axis>
        <xyz>0 -0 -1</xyz>
        <limit>
          <lower>-2.8973</lower>
          <upper>2.8973</upper>
          <effort>12</effort>
          <velocity>2.61</velocity>
        </limit>
        <dynamics>
          <spring_reference>0</spring_reference>
          <spring_stiffness>0</spring_stiffness>
        </dynamics>
        <use_parent_model_frame>1</use_parent_model_frame>
      </axis>
    </joint>
    <link name='panda_leftfinger'>
      <pose frame=''>0.088 -5 0.8676 3.14159 0 0.785398</pose>
      <inertial>
        <pose frame=''>0 0 0 0 -0 0</pose>
        <mass>0.68</mass>
        <inertia>
          <ixx>0.1</ixx>
          <ixy>0</ixy>
          <ixz>0</ixz>
          <iyy>0.1</iyy>
          <iyz>0</iyz>
          <izz>0.1</izz>
        </inertia>
      </inertial>
      <visual name='panda_leftfinger_visual'>
        <pose frame=''>0 0 0 0 -0 0</pose>
        <geometry>
          <mesh>
            <scale>1 1 1</scale>
            <uri>model://iiwa_panda_lwa4p_ur5e/meshes/panda/visual/finger.dae</uri>
          </mesh>
        </geometry>
        <material>
          <script>
            <name>Gazebo/Grey</name>
            <uri>file://media/materials/scripts/gazebo.material</uri>
          </script>
        </material>
      </visual>
      <gravity>1</gravity>
      <velocity_decay/>
    </link>
    <joint name='panda_finger_joint1' type='prismatic'>
      <child>panda_leftfinger</child>
      <parent>panda_link7</parent>
      <axis>
        <xyz>0.707107 -0.707107 0</xyz>
        <limit>
          <lower>0</lower>
          <upper>0.04</upper>
          <effort>20</effort>
          <velocity>0.2</velocity>
        </limit>
        <dynamics>
          <spring_reference>0</spring_reference>
          <spring_stiffness>0</spring_stiffness>
        </dynamics>
        <use_parent_model_frame>1</use_parent_model_frame>
      </axis>
    </joint>
    <link name='panda_rightfinger'>
      <pose frame=''>0.088 -5 0.8676 3.14159 0 0.785398</pose>
      <inertial>
        <pose frame=''>0 0 0 0 -0 0</pose>
        <mass>0.68</mass>
        <inertia>
          <ixx>0.1</ixx>
          <ixy>0</ixy>
          <ixz>0</ixz>
          <iyy>0.1</iyy>
          <iyz>0</iyz>
          <izz>0.1</izz>
        </inertia>
      </inertial>
      <visual name='panda_rightfinger_visual'>
        <pose frame=''>0 0 0 0 -0 -3.14159</pose>
        <geometry>
          <mesh>
            <scale>1 1 1</scale>
            <uri>model://iiwa_panda_lwa4p_ur5e/meshes/panda/visual/finger.dae</uri>
          </mesh>
        </geometry>
        <material>
          <script>
            <name>Gazebo/Grey</name>
            <uri>file://media/materials/scripts/gazebo.material</uri>
          </script>
        </material>
      </visual>
      <gravity>1</gravity>
      <velocity_decay/>
    </link>
    <joint name='panda_finger_joint2' type='prismatic'>
      <child>panda_rightfinger</child>
      <parent>panda_link7</parent>
      <axis>
        <xyz>-0.707107 0.707107 -0</xyz>
        <limit>
          <lower>0</lower>
          <upper>0.04</upper>
          <effort>20</effort>
          <velocity>0.2</velocity>
        </limit>
        <dynamics>
          <spring_reference>0</spring_reference>
          <spring_stiffness>0</spring_stiffness>
        </dynamics>
        <use_parent_model_frame>1</use_parent_model_frame>
      </axis>
    </joint>
    <link name='iiwa_link_0'>
      <pose frame=''>0 0 0 0 -0 0</pose>
      <inertial>
        <pose frame=''>-0.1 0 0.07 0 -0 0</pose>
        <mass>5</mass>
        <inertia>
          <ixx>0.05</ixx>
          <ixy>0</ixy>
          <ixz>0</ixz>
          <iyy>0.06</iyy>
          <iyz>0</iyz>
          <izz>0.03</izz>
        </inertia>
      </inertial>
      <collision name='iiwa_link_0_collision'>
        <pose frame=''>0 0 0 0 -0 0</pose>
        <geometry>
          <mesh>
            <scale>1 1 1</scale>
            <uri>model://iiwa_panda_lwa4p_ur5e/meshes/iiwa/collision/link_0.dae</uri>
          </mesh>
        </geometry>
        <surface>
          <contact>
            <ode/>
          </contact>
          <friction>
            <ode>
              <mu>0.2</mu>
              <mu2>0.2</mu2>
            </ode>
          </friction>
        </surface>
      </collision>
      <visual name='iiwa_link_0_visual'>
        <pose frame=''>0 0 0 0 -0 0</pose>
        <geometry>
          <mesh>
            <scale>1 1 1</scale>
            <uri>model://iiwa_panda_lwa4p_ur5e/meshes/iiwa/visual/link_0.dae</uri>
          </mesh>
        </geometry>
        <material>
          <script>
            <name>Gazebo/Grey</name>
            <uri>file://media/materials/scripts/gazebo.material</uri>
          </script>
        </material>
      </visual>
      <gravity>1</gravity>
      <velocity_decay/>
    </link>
    <joint name='world_iiwa_joint' type='fixed'>
      <child>iiwa_link_0</child>
      <parent>world</parent>
    </joint>
    <link name='iiwa_link_1'>
      <pose frame=''>0 0 0.1575 0 -0 0</pose>
      <inertial>
        <pose frame=''>0 -0.03 0.12 0 -0 0</pose>
        <mass>4</mass>
        <inertia>
          <ixx>0.1</ixx>
          <ixy>0</ixy>
          <ixz>0</ixz>
          <iyy>0.09</iyy>
          <iyz>0</iyz>
          <izz>0.02</izz>
        </inertia>
      </inertial>
      <collision name='iiwa_link_1_collision'>
        <pose frame=''>0 0 0 0 -0 0</pose>
        <geometry>
          <mesh>
            <scale>1 1 1</scale>
            <uri>model://iiwa_panda_lwa4p_ur5e/meshes/iiwa/collision/link_1.dae</uri>
          </mesh>
        </geometry>
        <surface>
          <contact>
            <ode/>
          </contact>
          <friction>
            <ode>
              <mu>0.2</mu>
              <mu2>0.2</mu2>
            </ode>
          </friction>
        </surface>
      </collision>
      <visual name='iiwa_link_1_visual'>
        <pose frame=''>0 0 0 0 -0 0</pose>
        <geometry>
          <mesh>
            <scale>1 1 1</scale>
            <uri>model://iiwa_panda_lwa4p_ur5e/meshes/iiwa/visual/link_1.dae</uri>
          </mesh>
        </geometry>
        <material>
          <script>
            <name>Gazebo/Orange</name>
            <uri>file://media/materials/scripts/gazebo.material</uri>
          </script>
        </material>
      </visual>
      <gravity>1</gravity>
      <velocity_decay/>
    </link>
    <joint name='iiwa_joint_1' type='revolute'>
      <child>iiwa_link_1</child>
      <parent>iiwa_link_0</parent>
      <axis>
        <xyz>0 0 1</xyz>
        <limit>
          <lower>-2.96706</lower>
          <upper>2.96706</upper>
          <effort>300</effort>
          <velocity>10</velocity>
        </limit>
        <dynamics>
          <damping>0</damping>
          <friction>0</friction>
          <spring_reference>0</spring_reference>
          <spring_stiffness>0</spring_stiffness>
        </dynamics>
        <use_parent_model_frame>1</use_parent_model_frame>
      </axis>
    </joint>
    <link name='iiwa_link_2'>
      <pose frame=''>0 0 0.36 1.5708 -0 -3.14159</pose>
      <inertial>
        <pose frame=''>0.0003 0.059 0.042 0 -0 0</pose>
        <mass>0.4</mass>
        <inertia>
          <ixx>0.05</ixx>
          <ixy>0</ixy>
          <ixz>0</ixz>
          <iyy>0.018</iyy>
          <iyz>0</iyz>
          <izz>0.044</izz>
        </inertia>
      </inertial>
      <collision name='iiwa_link_2_collision'>
        <pose frame=''>0 0 0 0 -0 0</pose>
        <geometry>
          <mesh>
            <scale>1 1 1</scale>
            <uri>model://iiwa_panda_lwa4p_ur5e/meshes/iiwa/collision/link_2.dae</uri>
          </mesh>
        </geometry>
        <surface>
          <contact>
            <ode/>
          </contact>
          <friction>
            <ode>
              <mu>0.2</mu>
              <mu2>0.2</mu2>
            </ode>
          </friction>
        </surface>
      </collision>
      <visual name='iiwa_link_2_visual'>
        <pose frame=''>0 0 0 0 -0 0</pose>
        <geometry>
          <mesh>
            <scale>1 1 1</scale>
            <uri>model://iiwa_panda_lwa4p_ur5e/meshes/iiwa/visual/link_2.dae</uri>
          </mesh>
        </geometry>
        <material>
          <script>
            <name>Gazebo/Orange</name>
            <uri>file://media/materials/scripts/gazebo.material</uri>
          </script>
        </material>
      </visual>
      <gravity>1</gravity>
      <velocity_decay/>
    </link>
    <joint name='iiwa_joint_2' type='revolute'>
      <child>iiwa_link_2</child>
      <parent>iiwa_link_1</parent>
      <axis>
        <xyz>-0 1 0</xyz>
        <limit>
          <lower>-2.0944</lower>
          <upper>2.0944</upper>
          <effort>300</effort>
          <velocity>10</velocity>
        </limit>
        <dynamics>
          <damping>0</damping>
          <friction>0</friction>
          <spring_reference>0</spring_reference>
          <spring_stiffness>0</spring_stiffness>
        </dynamics>
        <use_parent_model_frame>1</use_parent_model_frame>
      </axis>
    </joint>
    <link name='iiwa_link_3'>
      <pose frame=''>0 -0 0.5645 0 0 0</pose>
      <inertial>
        <pose frame=''>0 0.03 0.13 0 -0 0</pose>
        <mass>0.3</mass>
        <inertia>
          <ixx>0.08</ixx>
          <ixy>0</ixy>
          <ixz>0</ixz>
          <iyy>0.075</iyy>
          <iyz>0</iyz>
          <izz>0.01</izz>
        </inertia>
      </inertial>
      <collision name='iiwa_link_3_collision'>
        <pose frame=''>0 0 0 0 -0 0</pose>
        <geometry>
          <mesh>
            <scale>1 1 1</scale>
            <uri>model://iiwa_panda_lwa4p_ur5e/meshes/iiwa/collision/link_3.dae</uri>
          </mesh>
        </geometry>
        <surface>
          <contact>
            <ode/>
          </contact>
          <friction>
            <ode>
              <mu>0.2</mu>
              <mu2>0.2</mu2>
            </ode>
          </friction>
        </surface>
      </collision>
      <visual name='iiwa_link_3_visual'>
        <pose frame=''>0 0 0 0 -0 0</pose>
        <geometry>
          <mesh>
            <scale>1 1 1</scale>
            <uri>model://iiwa_panda_lwa4p_ur5e/meshes/iiwa/visual/link_3.dae</uri>
          </mesh>
        </geometry>
        <material>
          <script>
            <name>Gazebo/Orange</name>
            <uri>file://media/materials/scripts/gazebo.material</uri>
          </script>
        </material>
      </visual>
      <gravity>1</gravity>
      <velocity_decay/>
    </link>
    <joint name='iiwa_joint_3' type='revolute'>
      <child>iiwa_link_3</child>
      <parent>iiwa_link_2</parent>
      <axis>
        <xyz>0 0 1</xyz>
        <limit>
          <lower>-2.96706</lower>
          <upper>2.96706</upper>
          <effort>300</effort>
          <velocity>10</velocity>
        </limit>
        <dynamics>
          <damping>0</damping>
          <friction>0</friction>
          <spring_reference>0</spring_reference>
          <spring_stiffness>0</spring_stiffness>
        </dynamics>
        <use_parent_model_frame>1</use_parent_model_frame>
      </axis>
    </joint>
    <link name='iiwa_link_4'>
      <pose frame=''>0 -0 0.78 1.5708 0 0</pose>
      <inertial>
        <pose frame=''>0 0.067 0.034 0 -0 0</pose>
        <mass>0.27</mass>
        <inertia>
          <ixx>0.03</ixx>
          <ixy>0</ixy>
          <ixz>0</ixz>
          <iyy>0.01</iyy>
          <iyz>0</iyz>
          <izz>0.029</izz>
        </inertia>
      </inertial>
      <collision name='iiwa_link_4_collision'>
        <pose frame=''>0 0 0 0 -0 0</pose>
        <geometry>
          <mesh>
            <scale>1 1 1</scale>
            <uri>model://iiwa_panda_lwa4p_ur5e/meshes/iiwa/collision/link_4.dae</uri>
          </mesh>
        </geometry>
        <surface>
          <contact>
            <ode/>
          </contact>
          <friction>
            <ode>
              <mu>0.2</mu>
              <mu2>0.2</mu2>
            </ode>
          </friction>
        </surface>
      </collision>
      <visual name='iiwa_link_4_visual'>
        <pose frame=''>0 0 0 0 -0 0</pose>
        <geometry>
          <mesh>
            <scale>1 1 1</scale>
            <uri>model://iiwa_panda_lwa4p_ur5e/meshes/iiwa/visual/link_4.dae</uri>
          </mesh>
        </geometry>
        <material>
          <script>
            <name>Gazebo/Orange</name>
            <uri>file://media/materials/scripts/gazebo.material</uri>
          </script>
        </material>
      </visual>
      <gravity>1</gravity>
      <velocity_decay/>
    </link>
    <joint name='iiwa_joint_4' type='revolute'>
      <child>iiwa_link_4</child>
      <parent>iiwa_link_3</parent>
      <axis>
        <xyz>0 -1 0</xyz>
        <limit>
          <lower>-2.0944</lower>
          <upper>2.0944</upper>
          <effort>300</effort>
          <velocity>10</velocity>
        </limit>
        <dynamics>
          <damping>0</damping>
          <friction>0</friction>
          <spring_reference>0</spring_reference>
          <spring_stiffness>0</spring_stiffness>
        </dynamics>
        <use_parent_model_frame>1</use_parent_model_frame>
      </axis>
    </joint>
    <link name='iiwa_link_5'>
      <pose frame=''>0 -0 0.9645 0 -0 -3.14159</pose>
      <inertial>
        <pose frame=''>0.0001 0.021 0.076 0 -0 0</pose>
        <mass>0.17</mass>
        <inertia>
          <ixx>0.02</ixx>
          <ixy>0</ixy>
          <ixz>0</ixz>
          <iyy>0.018</iyy>
          <iyz>0</iyz>
          <izz>0.005</izz>
        </inertia>
      </inertial>
      <collision name='iiwa_link_5_collision'>
        <pose frame=''>0 0 0 0 -0 0</pose>
        <geometry>
          <mesh>
            <scale>1 1 1</scale>
            <uri>model://iiwa_panda_lwa4p_ur5e/meshes/iiwa/collision/link_5.dae</uri>
          </mesh>
        </geometry>
        <surface>
          <contact>
            <ode/>
          </contact>
          <friction>
            <ode>
              <mu>0.2</mu>
              <mu2>0.2</mu2>
            </ode>
          </friction>
        </surface>
      </collision>
      <visual name='iiwa_link_5_visual'>
        <pose frame=''>0 0 0 0 -0 0</pose>
        <geometry>
          <mesh>
            <scale>1 1 1</scale>
            <uri>model://iiwa_panda_lwa4p_ur5e/meshes/iiwa/visual/link_5.dae</uri>
          </mesh>
        </geometry>
        <material>
          <script>
            <name>Gazebo/Orange</name>
            <uri>file://media/materials/scripts/gazebo.material</uri>
          </script>
        </material>
      </visual>
      <gravity>1</gravity>
      <velocity_decay/>
    </link>
    <joint name='iiwa_joint_5' type='revolute'>
      <child>iiwa_link_5</child>
      <parent>iiwa_link_4</parent>
      <axis>
        <xyz>0 0 1</xyz>
        <limit>
          <lower>-2.96706</lower>
          <upper>2.96706</upper>
          <effort>300</effort>
          <velocity>10</velocity>
        </limit>
        <dynamics>
          <damping>0</damping>
          <friction>0</friction>
          <spring_reference>0</spring_reference>
          <spring_stiffness>0</spring_stiffness>
        </dynamics>
        <use_parent_model_frame>1</use_parent_model_frame>
      </axis>
    </joint>
    <link name='iiwa_link_6'>
      <pose frame=''>0 0 1.18 1.5708 -0 -3.14159</pose>
      <inertial>
        <pose frame=''>0 0.0006 0.0004 0 -0 0</pose>
        <mass>0.18</mass>
        <inertia>
          <ixx>0.025</ixx>
          <ixy>0</ixy>
          <ixz>0</ixz>
          <iyy>0.0136</iyy>
          <iyz>0</iyz>
          <izz>0.0247</izz>
        </inertia>
      </inertial>
      <collision name='iiwa_link_6_collision'>
        <pose frame=''>0 0 0 0 -0 0</pose>
        <geometry>
          <mesh>
            <scale>1 1 1</scale>
            <uri>model://iiwa_panda_lwa4p_ur5e/meshes/iiwa/collision/link_6.dae</uri>
          </mesh>
        </geometry>
        <surface>
          <contact>
            <ode/>
          </contact>
          <friction>
            <ode>
              <mu>0.2</mu>
              <mu2>0.2</mu2>
            </ode>
          </friction>
        </surface>
      </collision>
      <visual name='iiwa_link_6_visual'>
        <pose frame=''>0 0 0 0 -0 0</pose>
        <geometry>
          <mesh>
            <scale>1 1 1</scale>
            <uri>model://iiwa_panda_lwa4p_ur5e/meshes/iiwa/visual/link_6.dae</uri>
          </mesh>
        </geometry>
        <material>
          <script>
            <name>Gazebo/Orange</name>
            <uri>file://media/materials/scripts/gazebo.material</uri>
          </script>
        </material>
      </visual>
      <gravity>1</gravity>
      <velocity_decay/>
    </link>
    <joint name='iiwa_joint_6' type='revolute'>
      <child>iiwa_link_6</child>
      <parent>iiwa_link_5</parent>
      <axis>
        <xyz>-0 1 -0</xyz>
        <limit>
          <lower>-2.0944</lower>
          <upper>2.0944</upper>
          <effort>300</effort>
          <velocity>10</velocity>
        </limit>
        <dynamics>
          <damping>0</damping>
          <friction>0</friction>
          <spring_reference>0</spring_reference>
          <spring_stiffness>0</spring_stiffness>
        </dynamics>
        <use_parent_model_frame>1</use_parent_model_frame>
      </axis>
    </joint>
    <link name='iiwa_link_7'>
      <pose frame=''>0 0 1.261 0 0 0</pose>
      <inertial>
        <pose frame=''>0 0 0.035625 0 -0 0</pose>
        <mass>0.08</mass>
        <inertia>
          <ixx>0.0101817</ixx>
          <ixy>0</ixy>
          <ixz>0</ixz>
          <iyy>0.0117117</iyy>
          <iyz>-4.37114e-12</iyz>
          <izz>0.0118</izz>
        </inertia>
      </inertial>
      <collision name='iiwa_link_7_collision'>
        <pose frame=''>0 0 0 0 -0 0</pose>
        <geometry>
          <mesh>
            <scale>1 1 1</scale>
            <uri>model://iiwa_panda_lwa4p_ur5e/meshes/iiwa/collision/link_7.dae</uri>
          </mesh>
        </geometry>
        <surface>
          <contact>
            <ode/>
          </contact>
          <friction>
            <ode>
              <mu>0.2</mu>
              <mu2>0.2</mu2>
            </ode>
          </friction>
        </surface>
      </collision>
      <collision name='iiwa_link_7_fixed_joint_lump__base_link_link_collision_1'>
        <pose frame=''>0 -0 0.07 0 -0 0</pose>
        <geometry>
          <mesh>
            <scale>1 1 1</scale>
            <uri>model://iiwa_panda_lwa4p_ur5e/meshes/iiwa/collision/COL_base.dae</uri>
          </mesh>
        </geometry>
      </collision>
      <visual name='iiwa_link_7_visual'>
        <pose frame=''>0 0 0 0 -0 0</pose>
        <geometry>
          <mesh>
            <scale>1 1 1</scale>
            <uri>model://iiwa_panda_lwa4p_ur5e/meshes/iiwa/visual/link_7.dae</uri>
          </mesh>
        </geometry>
        <material>
          <script>
            <name>Gazebo/Grey</name>
            <uri>file://media/materials/scripts/gazebo.material</uri>
          </script>
        </material>
      </visual>
      <visual name='iiwa_link_7_fixed_joint_lump__base_link_link_visual_1'>
        <pose frame=''>0 -0 0.07 0 -0 0</pose>
        <geometry>
          <mesh>
            <scale>1 1 1</scale>
            <uri>model://iiwa_panda_lwa4p_ur5e/meshes/iiwa/visual/VIS_base.dae</uri>
          </mesh>
        </geometry>
      </visual>
      <gravity>1</gravity>
      <velocity_decay/>
    </link>
    <joint name='iiwa_joint_7' type='revolute'>
      <child>iiwa_link_7</child>
      <parent>iiwa_link_6</parent>
      <axis>
        <xyz>0 0 1</xyz>
        <limit>
          <lower>-3.05433</lower>
          <upper>3.05433</upper>
          <effort>300</effort>
          <velocity>10</velocity>
        </limit>
        <dynamics>
          <damping>0</damping>
          <friction>0</friction>
          <spring_reference>0</spring_reference>
          <spring_stiffness>0</spring_stiffness>
        </dynamics>
        <use_parent_model_frame>1</use_parent_model_frame>
      </axis>
      <physics>
        <provide_feedback>1</provide_feedback>
        <ode>
          <provide_feedback>1</provide_feedback>
          <limit>
            <cfm>0</cfm>
            <erp>0.2</erp>
          </limit>
        </ode>
      </physics>
    </joint>
    <link name='gripper_left_link'>
      <pose frame=''>-0.085 -0 1.356 -3.14159 -0 1.5708</pose>
      <inertial>
        <pose frame=''>0 0 0 0 -0 0</pose>
        <mass>0.01</mass>
        <inertia>
          <ixx>0.0002</ixx>
          <ixy>0</ixy>
          <ixz>0</ixz>
          <iyy>0.000195</iyy>
          <iyz>0</iyz>
          <izz>2.1e-05</izz>
        </inertia>
      </inertial>
      <collision name='gripper_left_link_collision'>
        <pose frame=''>0 -0 -0.072 3.14159 0 1.5708</pose>
        <geometry>
          <mesh>
            <scale>1 1 1</scale>
            <uri>model://iiwa_panda_lwa4p_ur5e/meshes/iiwa/collision/COL_gripper_left.dae</uri>
          </mesh>
        </geometry>
      </collision>
      <visual name='gripper_left_link_visual'>
        <pose frame=''>0 -0 -0.072 3.14159 0 1.5708</pose>
        <geometry>
          <mesh>
            <scale>1 1 1</scale>
            <uri>model://iiwa_panda_lwa4p_ur5e/meshes/iiwa/visual/VIS_gripper_left.dae</uri>
          </mesh>
        </geometry>
      </visual>
    </link>
    <joint name='gripper_left_joint' type='prismatic'>
      <child>gripper_left_link</child>
      <parent>iiwa_link_7</parent>
      <axis>
        <xyz>1 -0 -0</xyz>
        <limit>
          <lower>0</lower>
          <upper>0.0704</upper>
          <effort>100</effort>
          <velocity>1</velocity>
        </limit>
        <dynamics>
          <damping>1</damping>
          <friction>0</friction>
          <spring_reference>0</spring_reference>
          <spring_stiffness>0</spring_stiffness>
        </dynamics>
        <use_parent_model_frame>1</use_parent_model_frame>
      </axis>
    </joint>
    <link name='gripper_right_link'>
      <pose frame=''>0.085 -0 1.356 -3.14159 0 -1.5708</pose>
      <inertial>
        <pose frame=''>0 0 0 0 -0 0</pose>
        <mass>0.01</mass>
        <inertia>
          <ixx>0.0002</ixx>
          <ixy>0</ixy>
          <ixz>0</ixz>
          <iyy>0.000195</iyy>
          <iyz>0</iyz>
          <izz>2.1e-05</izz>
        </inertia>
      </inertial>
      <collision name='gripper_right_link_collision'>
        <pose frame=''>-0 -0 -0.072 3.14159 -0 -1.5708</pose>
        <geometry>
          <mesh>
            <scale>1 1 1</scale>
            <uri>model://iiwa_panda_lwa4p_ur5e/meshes/iiwa/collision/COL_gripper_right.dae</uri>
          </mesh>
        </geometry>
      </collision>
      <visual name='gripper_right_link_visual'>
        <pose frame=''>-0 -0 -0.072 3.14159 -0 -1.5708</pose>
        <geometry>
          <mesh>
            <scale>1 1 1</scale>
            <uri>model://iiwa_panda_lwa4p_ur5e/meshes/iiwa/visual/VIS_gripper_right.dae</uri>
          </mesh>
        </geometry>
      </visual>
    </link>
    <joint name='gripper_right_joint' type='prismatic'>
      <child>gripper_right_link</child>
      <parent>iiwa_link_7</parent>
      <axis>
        <xyz>-1 -0 -0</xyz>
        <limit>
          <lower>0</lower>
          <upper>0.0704</upper>
          <effort>100</effort>
          <velocity>1</velocity>
        </limit>
        <dynamics>
          <damping>1</damping>
          <friction>0</friction>
          <spring_reference>0</spring_reference>
          <spring_stiffness>0</spring_stiffness>
        </dynamics>
        <use_parent_model_frame>1</use_parent_model_frame>
      </axis>
    </joint>
    <link name='base_link'>
      <pose frame=''>0 3 0 0 -0 0</pose>
      <inertial>
        <pose frame=''>0 0 0 0 -0 0</pose>
        <mass>4</mass>
        <inertia>
          <ixx>0.00443333</ixx>
          <ixy>0</ixy>
          <ixz>0</ixz>
          <iyy>0.00443333</iyy>
          <iyz>0</iyz>
          <izz>0.0072</izz>
        </inertia>
      </inertial>
      <collision name='base_link_collision'>
        <pose frame=''>0 0 0 0 -0 0</pose>
        <geometry>
          <mesh>
            <scale>1 1 1</scale>
            <uri>model://iiwa_panda_lwa4p_ur5e/meshes/ur5e/collision/base.stl</uri>
          </mesh>
        </geometry>
      </collision>
      <visual name='base_link_visual'>
        <pose frame=''>0 0 0 0 -0 0</pose>
        <geometry>
          <mesh>
            <scale>1 1 1</scale>
            <uri>model://iiwa_panda_lwa4p_ur5e/meshes/ur5e/visual/base.dae</uri>
          </mesh>
        </geometry>
      </visual>
    </link>
    <joint name='world_joint' type='fixed'>
      <child>base_link</child>
      <parent>world</parent>
    </joint>
    <link name='shoulder_link'>
      <pose frame=''>0 3 0.163 0 -0 0</pose>
      <inertial>
        <pose frame=''>0 0 0 0 -0 0</pose>
        <mass>3.7</mass>
        <inertia>
          <ixx>0.0102675</ixx>
          <ixy>0</ixy>
          <ixz>0</ixz>
          <iyy>0.0102675</iyy>
          <iyz>0</iyz>
          <izz>0.00666</izz>
        </inertia>
      </inertial>
      <collision name='shoulder_link_collision'>
        <pose frame=''>0 0 0 0 -0 0</pose>
        <geometry>
          <mesh>
            <scale>1 1 1</scale>
            <uri>model://iiwa_panda_lwa4p_ur5e/meshes/ur5e/collision/shoulder.stl</uri>
          </mesh>
        </geometry>
        <surface>
          <contact>
            <ode/>
          </contact>
          <friction>
            <ode/>
          </friction>
        </surface>
      </collision>
      <visual name='shoulder_link_visual'>
        <pose frame=''>0 0 0 0 -0 0</pose>
        <geometry>
          <mesh>
            <scale>1 1 1</scale>
            <uri>model://iiwa_panda_lwa4p_ur5e/meshes/ur5e/visual/shoulder.dae</uri>
          </mesh>
        </geometry>
        <material>
          <script>
            <uri>__default__</uri>
            <name>__default__</name>
          </script>
        </material>
      </visual>
      <gravity>1</gravity>
      <velocity_decay/>
      <self_collide>1</self_collide>
    </link>
    <joint name='shoulder_pan_joint' type='revolute'>
      <child>shoulder_link</child>
      <parent>base_link</parent>
      <axis>
        <xyz>0 0 1</xyz>
        <limit>
          <lower>-3.14159</lower>
          <upper>3.14159</upper>
          <effort>150</effort>
          <velocity>3.14</velocity>
        </limit>
        <dynamics>
          <damping>0</damping>
          <friction>0</friction>
          <spring_reference>0</spring_reference>
          <spring_stiffness>0</spring_stiffness>
        </dynamics>
        <use_parent_model_frame>1</use_parent_model_frame>
      </axis>
    </joint>
    <link name='upper_arm_link'>
      <pose frame=''>0 3.138 0.163 3.14159 1.57079 3.14159</pose>
      <inertial>
        <pose frame=''>0 0 0.2125 0 -0 0</pose>
        <mass>8.393</mass>
        <inertia>
          <ixx>0.133886</ixx>
          <ixy>0</ixy>
          <ixz>0</ixz>
          <iyy>0.133886</iyy>
          <iyz>0</iyz>
          <izz>0.0151074</izz>
        </inertia>
      </inertial>
      <collision name='upper_arm_link_collision'>
        <pose frame=''>0 0 0 0 -0 0</pose>
        <geometry>
          <mesh>
            <scale>1 1 1</scale>
            <uri>model://iiwa_panda_lwa4p_ur5e/meshes/ur5e/collision/upperarm.stl</uri>
          </mesh>
        </geometry>
        <surface>
          <contact>
            <ode/>
          </contact>
          <friction>
            <ode/>
          </friction>
        </surface>
      </collision>
      <visual name='upper_arm_link_visual'>
        <pose frame=''>0 0 0 0 -0 0</pose>
        <geometry>
          <mesh>
            <scale>1 1 1</scale>
            <uri>model://iiwa_panda_lwa4p_ur5e/meshes/ur5e/visual/upperarm.dae</uri>
          </mesh>
        </geometry>
        <material>
          <script>
            <uri>__default__</uri>
            <name>__default__</name>
          </script>
        </material>
      </visual>
      <gravity>1</gravity>
      <velocity_decay/>
      <self_collide>1</self_collide>
    </link>
    <joint name='shoulder_lift_joint' type='revolute'>
      <child>upper_arm_link</child>
      <parent>shoulder_link</parent>
      <axis>
        <xyz>0 1 0</xyz>
        <limit>
          <lower>-3.14159</lower>
          <upper>3.14159</upper>
          <effort>150</effort>
          <velocity>3.14</velocity>
        </limit>
        <dynamics>
          <damping>0</damping>
          <friction>0</friction>
          <spring_reference>0</spring_reference>
          <spring_stiffness>0</spring_stiffness>
        </dynamics>
        <use_parent_model_frame>1</use_parent_model_frame>
      </axis>
    </joint>
    <link name='forearm_link'>
      <pose frame=''>0.425 3.007 0.163 3.14159 1.57079 3.14159</pose>
      <inertial>
        <pose frame=''>0 0 0.196 0 -0 0</pose>
        <mass>2.275</mass>
        <inertia>
          <ixx>0.0311796</ixx>
          <ixy>0</ixy>
          <ixz>0</ixz>
          <iyy>0.0311796</iyy>
          <iyz>0</iyz>
          <izz>0.004095</izz>
        </inertia>
      </inertial>
      <collision name='forearm_link_collision'>
        <pose frame=''>0 0 0 0 -0 0</pose>
        <geometry>
          <mesh>
            <scale>1 1 1</scale>
            <uri>model://iiwa_panda_lwa4p_ur5e/meshes/ur5e/collision/forearm.stl</uri>
          </mesh>
        </geometry>
        <surface>
          <contact>
            <ode/>
          </contact>
          <friction>
            <ode/>
          </friction>
        </surface>
      </collision>
      <visual name='forearm_link_visual'>
        <pose frame=''>0 0 0 0 -0 0</pose>
        <geometry>
          <mesh>
            <scale>1 1 1</scale>
            <uri>model://iiwa_panda_lwa4p_ur5e/meshes/ur5e/visual/forearm.dae</uri>
          </mesh>
        </geometry>
        <material>
          <script>
            <uri>__default__</uri>
            <name>__default__</name>
          </script>
        </material>
      </visual>
      <gravity>1</gravity>
      <velocity_decay/>
      <self_collide>1</self_collide>
    </link>
    <joint name='elbow_joint' type='revolute'>
      <child>forearm_link</child>
      <parent>upper_arm_link</parent>
      <axis>
        <xyz>0 1 0</xyz>
        <limit>
          <lower>-3.14159</lower>
          <upper>3.14159</upper>
          <effort>150</effort>
          <velocity>3.14</velocity>
        </limit>
        <dynamics>
          <damping>0</damping>
          <friction>0</friction>
          <spring_reference>0</spring_reference>
          <spring_stiffness>0</spring_stiffness>
        </dynamics>
        <use_parent_model_frame>1</use_parent_model_frame>
      </axis>
    </joint>
    <link name='wrist_1_link'>
      <pose frame=''>0.817 3.007 0.163 3.14159 0 3.14159</pose>
      <inertial>
        <pose frame=''>0 0.127 0 0 -0 0</pose>
        <mass>1.219</mass>
        <inertia>
          <ixx>0.0025599</ixx>
          <ixy>0</ixy>
          <ixz>0</ixz>
          <iyy>0.0025599</iyy>
          <iyz>0</iyz>
          <izz>0.0021942</izz>
        </inertia>
      </inertial>
      <collision name='wrist_1_link_collision'>
        <pose frame=''>0 0 0 0 -0 0</pose>
        <geometry>
          <mesh>
            <scale>1 1 1</scale>
            <uri>model://iiwa_panda_lwa4p_ur5e/meshes/ur5e/collision/wrist1.stl</uri>
          </mesh>
        </geometry>
        <surface>
          <contact>
            <ode/>
          </contact>
          <friction>
            <ode/>
          </friction>
        </surface>
      </collision>
      <visual name='wrist_1_link_visual'>
        <pose frame=''>0 0 0 0 -0 0</pose>
        <geometry>
          <mesh>
            <scale>1 1 1</scale>
            <uri>model://iiwa_panda_lwa4p_ur5e/meshes/ur5e/visual/wrist1.dae</uri>
          </mesh>
        </geometry>
        <material>
          <script>
            <uri>__default__</uri>
            <name>__default__</name>
          </script>
        </material>
      </visual>
      <gravity>1</gravity>
      <velocity_decay/>
      <self_collide>1</self_collide>
    </link>
    <joint name='wrist_1_joint' type='revolute'>
      <child>wrist_1_link</child>
      <parent>forearm_link</parent>
      <axis>
        <xyz>0 1 0</xyz>
        <limit>
          <lower>-3.14159</lower>
          <upper>3.14159</upper>
          <effort>28</effort>
          <velocity>6.28</velocity>
        </limit>
        <dynamics>
          <damping>0</damping>
          <friction>0</friction>
          <spring_reference>0</spring_reference>
          <spring_stiffness>0</spring_stiffness>
        </dynamics>
        <use_parent_model_frame>1</use_parent_model_frame>
      </axis>
    </joint>
    <link name='wrist_2_link'>
      <pose frame=''>0.817 3.134 0.163 3.14159 0 3.14159</pose>
      <inertial>
        <pose frame=''>0 0 0.1 0 -0 0</pose>
        <mass>1.219</mass>
        <inertia>
          <ixx>0.0025599</ixx>
          <ixy>0</ixy>
          <ixz>0</ixz>
          <iyy>0.0025599</iyy>
          <iyz>0</iyz>
          <izz>0.0021942</izz>
        </inertia>
      </inertial>
      <collision name='wrist_2_link_collision'>
        <pose frame=''>0 0 0 0 -0 0</pose>
        <geometry>
          <mesh>
            <scale>1 1 1</scale>
            <uri>model://iiwa_panda_lwa4p_ur5e/meshes/ur5e/collision/wrist2.stl</uri>
          </mesh>
        </geometry>
        <surface>
          <contact>
            <ode/>
          </contact>
          <friction>
            <ode/>
          </friction>
        </surface>
      </collision>
      <visual name='wrist_2_link_visual'>
        <pose frame=''>0 0 0 0 -0 0</pose>
        <geometry>
          <mesh>
            <scale>1 1 1</scale>
            <uri>model://iiwa_panda_lwa4p_ur5e/meshes/ur5e/visual/wrist2.dae</uri>
          </mesh>
        </geometry>
        <material>
          <script>
            <uri>__default__</uri>
            <name>__default__</name>
          </script>
        </material>
      </visual>
      <gravity>1</gravity>
      <velocity_decay/>
      <self_collide>1</self_collide>
    </link>
    <joint name='wrist_2_joint' type='revolute'>
      <child>wrist_2_link</child>
      <parent>wrist_1_link</parent>
      <axis>
        <xyz>0 0 -1</xyz>
        <limit>
          <lower>-3.14159</lower>
          <upper>3.14159</upper>
          <effort>28</effort>
          <velocity>6.28</velocity>
        </limit>
        <dynamics>
          <damping>0</damping>
          <friction>0</friction>
          <spring_reference>0</spring_reference>
          <spring_stiffness>0</spring_stiffness>
        </dynamics>
        <use_parent_model_frame>1</use_parent_model_frame>
      </axis>
    </joint>
    <link name='wrist_3_link'>
      <pose frame=''>0.817 3.134 0.063 3.14159 0 3.14159</pose>
      <inertial>
        <pose frame=''>0 0.082123 0 1.5708 -0 0</pose>
        <mass>0.2379</mass>
        <inertia>
          <ixx>0.000291462</ixx>
          <ixy>0</ixy>
          <ixz>0</ixz>
          <iyy>0.00182146</iyy>
          <iyz>-4.372e-12</iyz>
          <izz>0.00193212</izz>
        </inertia>
      </inertial>
      <collision name='wrist_3_link_collision'>
        <pose frame=''>0 0 0 0 -0 0</pose>
        <geometry>
          <mesh>
            <scale>1 1 1</scale>
            <uri>model://iiwa_panda_lwa4p_ur5e/meshes/ur5e/collision/wrist3.stl</uri>
          </mesh>
        </geometry>
        <surface>
          <contact>
            <ode/>
          </contact>
          <friction>
            <ode/>
          </friction>
        </surface>
      </collision>
      <collision name='wrist_3_link_fixed_joint_lump__ee_link_collision_1'>
        <pose frame=''>-0 0.09 0 0 -0 1.5708</pose>
        <geometry>
          <box>
            <size>0.01 0.01 0.01</size>
          </box>
        </geometry>
        <surface>
          <contact>
            <ode/>
          </contact>
          <friction>
            <ode/>
          </friction>
        </surface>
      </collision>
      <collision name='wrist_3_link_fixed_joint_lump__gripper_base_link_ur5e_collision_2'>
        <pose frame=''>0 0.126 0 -1.5708 0 0</pose>
        <geometry>
          <mesh>
            <scale>1 1 1</scale>
            <uri>model://iiwa_panda_lwa4p_ur5e/meshes/iiwa/collision/COL_base.dae</uri>
          </mesh>
        </geometry>
      </collision>
      <visual name='wrist_3_link_visual'>
        <pose frame=''>0 0 0 0 -0 0</pose>
        <geometry>
          <mesh>
            <scale>1 1 1</scale>
            <uri>model://iiwa_panda_lwa4p_ur5e/meshes/ur5e/visual/wrist3.dae</uri>
          </mesh>
        </geometry>
        <material>
          <script>
            <uri>__default__</uri>
            <name>__default__</name>
          </script>
        </material>
      </visual>
      <visual name='wrist_3_link_fixed_joint_lump__gripper_base_link_ur5e_visual_1'>
        <pose frame=''>0 0.126 0 -1.5708 0 0</pose>
        <geometry>
          <mesh>
            <scale>1 1 1</scale>
            <uri>model://iiwa_panda_lwa4p_ur5e/meshes/iiwa/visual/VIS_base.dae</uri>
          </mesh>
        </geometry>
      </visual>
      <velocity_decay/>
      <gravity>1</gravity>
      <velocity_decay/>
      <self_collide>1</self_collide>
    </link>
    <joint name='wrist_3_joint' type='revolute'>
      <child>wrist_3_link</child>
      <parent>wrist_2_link</parent>
      <axis>
        <xyz>0 1 0</xyz>
        <limit>
          <lower>-3.14159</lower>
          <upper>3.14159</upper>
          <effort>28</effort>
          <velocity>6.28</velocity>
        </limit>
        <dynamics>
          <damping>0</damping>
          <friction>0</friction>
          <spring_reference>0</spring_reference>
          <spring_stiffness>0</spring_stiffness>
        </dynamics>
        <use_parent_model_frame>1</use_parent_model_frame>
      </axis>
    </joint>
    <link name='gripper_left_link_ur5e'>
      <pose frame=''>0.902 3.285 0.063 2.0956 -1.57079 -0.524813</pose>
      <inertial>
        <pose frame=''>0 0 0 0 -0 0</pose>
        <mass>0.01</mass>
        <inertia>
          <ixx>0.0002</ixx>
          <ixy>0</ixy>
          <ixz>0</ixz>
          <iyy>0.000195</iyy>
          <iyz>0</iyz>
          <izz>2.1e-05</izz>
        </inertia>
      </inertial>
      <collision name='gripper_left_link_ur5e_collision'>
        <pose frame=''>0 -0 -0.072 3.14159 0 1.5708</pose>
        <geometry>
          <mesh>
            <scale>1 1 1</scale>
            <uri>model://iiwa_panda_lwa4p_ur5e/meshes/iiwa/collision/COL_gripper_left.dae</uri>
          </mesh>
        </geometry>
      </collision>
      <visual name='gripper_left_link_ur5e_visual'>
        <pose frame=''>0 -0 -0.072 3.14159 0 1.5708</pose>
        <geometry>
          <mesh>
            <scale>1 1 1</scale>
            <uri>model://iiwa_panda_lwa4p_ur5e/meshes/iiwa/visual/VIS_gripper_left.dae</uri>
          </mesh>
        </geometry>
      </visual>
    </link>
    <joint name='gripper_left_joint_ur5e' type='prismatic'>
      <child>gripper_left_link_ur5e</child>
      <parent>wrist_3_link</parent>
      <axis>
        <xyz>-1 -0 -0</xyz>
        <limit>
          <lower>0</lower>
          <upper>0.0704</upper>
          <effort>100</effort>
          <velocity>1</velocity>
        </limit>
        <dynamics>
          <damping>1</damping>
          <friction>0</friction>
          <spring_reference>0</spring_reference>
          <spring_stiffness>0</spring_stiffness>
        </dynamics>
        <use_parent_model_frame>1</use_parent_model_frame>
      </axis>
    </joint>
    <link name='gripper_right_link_ur5e'>
      <pose frame=''>0.732 3.285 0.063 2.09571 1.57079 0.524923</pose>
      <inertial>
        <pose frame=''>0 0 0 0 -0 0</pose>
        <mass>0.01</mass>
        <inertia>
          <ixx>0.0002</ixx>
          <ixy>0</ixy>
          <ixz>0</ixz>
          <iyy>0.000195</iyy>
          <iyz>0</iyz>
          <izz>2.1e-05</izz>
        </inertia>
      </inertial>
      <collision name='gripper_right_link_ur5e_collision'>
        <pose frame=''>-0 -0 -0.072 3.14159 -0 -1.5708</pose>
        <geometry>
          <mesh>
            <scale>1 1 1</scale>
            <uri>model://iiwa_panda_lwa4p_ur5e/meshes/iiwa/collision/COL_gripper_right.dae</uri>
          </mesh>
        </geometry>
      </collision>
      <visual name='gripper_right_link_ur5e_visual'>
        <pose frame=''>-0 -0 -0.072 3.14159 -0 -1.5708</pose>
        <geometry>
          <mesh>
            <scale>1 1 1</scale>
            <uri>model://iiwa_panda_lwa4p_ur5e/meshes/iiwa/visual/VIS_gripper_right.dae</uri>
          </mesh>
        </geometry>
      </visual>
    </link>
    <joint name='gripper_right_joint_ur5e' type='prismatic'>
      <child>gripper_right_link_ur5e</child>
      <parent>wrist_3_link</parent>
      <axis>
        <xyz>1 -0 -0</xyz>
        <limit>
          <lower>0</lower>
          <upper>0.0704</upper>
          <effort>100</effort>
          <velocity>1</velocity>
        </limit>
        <dynamics>
          <damping>1</damping>
          <friction>0</friction>
          <spring_reference>0</spring_reference>
          <spring_stiffness>0</spring_stiffness>
        </dynamics>
        <use_parent_model_frame>1</use_parent_model_frame>
      </axis>
    </joint>
    <plugin name='ft_sensor' filename='libgazebo_ros_ft_sensor.so'>
      <updateRate>50.0</updateRate>
      <topicName>/iiwa/state/CartesianWrench</topicName>
      <jointName>iiwa_joint_7</jointName>
    </plugin>
    <plugin name='gazebo_grasp_fix' filename='libgazebo_grasp_fix.so'>
      <arm>
        <arm_name>iiwa</arm_name>
        <palm_link>iiwa_link_7</palm_link>
        <gripper_link>gripper_right_link</gripper_link>
        <gripper_link>gripper_left_link</gripper_link>
      </arm>
      <forces_angle_tolerance>100</forces_angle_tolerance>
      <update_rate>4</update_rate>
      <grip_count_threshold>4</grip_count_threshold>
      <max_grip_count>8</max_grip_count>
      <release_tolerance>0.005</release_tolerance>
      <disable_collisions_on_attach>0</disable_collisions_on_attach>
      <contact_topic>__default_topic__</contact_topic>
    </plugin>
    <plugin name='gazebo_ros_control' filename='libgazebo_ros_control.so'>
      <robotNamespace>/iiwa</robotNamespace>
    </plugin>
    <plugin name='gazebo_ros_control' filename='libgazebo_ros_control.so'>
      <robotNamespace>/panda</robotNamespace>
    </plugin>
    <plugin name='gazebo_ros_control' filename='libgazebo_ros_control.so'>
      <legacyModeNS>0</legacyModeNS>
      <robotNamespace>/arm</robotNamespace>
      <robotSimType>gazebo_ros_control/DefaultRobotHWSim</robotSimType>
    </plugin>
    <plugin name='gazebo_ros_control' filename='libgazebo_ros_control.so'>
      <legacyModeNS>0</legacyModeNS>
      <robotNamespace>/svh/svh_ros_control_node</robotNamespace>
      <robotSimType>gazebo_ros_control/DefaultRobotHWSim</robotSimType>
    </plugin>
    <plugin name='svh_hand_j3_mimic_joint_plugin' filename='libroboticsgroup_gazebo_mimic_joint_plugin.so'>
      <joint>svh_hand_Thumb_Flexion</joint>
      <mimicJoint>svh_hand_j3</mimicJoint>
      <hasPID/>
      <multiplier>1.01511</multiplier>
      <offset>0</offset>
      <sensitiveness>0.0</sensitiveness>
      <maxEffort>100.0</maxEffort>
      <robotNamespace>/svh/svh_ros_control_node</robotNamespace>
    </plugin>
    <plugin name='svh_hand_j4_mimic_joint_plugin' filename='libroboticsgroup_gazebo_mimic_joint_plugin.so'>
      <joint>svh_hand_Thumb_Flexion</joint>
      <mimicJoint>svh_hand_j4</mimicJoint>
      <hasPID/>
      <multiplier>1.44889</multiplier>
      <offset>0</offset>
      <sensitiveness>0.0</sensitiveness>
      <maxEffort>100.0</maxEffort>
      <robotNamespace>/svh/svh_ros_control_node</robotNamespace>
    </plugin>
    <plugin name='svh_hand_j14_mimic_joint_plugin' filename='libroboticsgroup_gazebo_mimic_joint_plugin.so'>
      <joint>svh_hand_Index_Finger_Distal</joint>
      <mimicJoint>svh_hand_j14</mimicJoint>
      <hasPID/>
      <multiplier>1.045</multiplier>
      <offset>0</offset>
      <sensitiveness>0.0</sensitiveness>
      <maxEffort>100.0</maxEffort>
      <robotNamespace>/svh/svh_ros_control_node</robotNamespace>
    </plugin>
    <plugin name='svh_hand_j15_mimic_joint_plugin' filename='libroboticsgroup_gazebo_mimic_joint_plugin.so'>
      <joint>svh_hand_Middle_Finger_Distal</joint>
      <mimicJoint>svh_hand_j15</mimicJoint>
      <hasPID/>
      <multiplier>1.0454</multiplier>
      <offset>0</offset>
      <sensitiveness>0.0</sensitiveness>
      <maxEffort>100.0</maxEffort>
      <robotNamespace>/svh/svh_ros_control_node</robotNamespace>
    </plugin>
    <plugin name='svh_hand_j12_mimic_joint_plugin' filename='libroboticsgroup_gazebo_mimic_joint_plugin.so'>
      <joint>svh_hand_Ring_Finger</joint>
      <mimicJoint>svh_hand_j12</mimicJoint>
      <hasPID/>
      <multiplier>1.3588</multiplier>
      <offset>0</offset>
      <sensitiveness>0.0</sensitiveness>
      <maxEffort>100.0</maxEffort>
      <robotNamespace>/svh/svh_ros_control_node</robotNamespace>
    </plugin>
    <plugin name='svh_hand_j16_mimic_joint_plugin' filename='libroboticsgroup_gazebo_mimic_joint_plugin.so'>
      <joint>svh_hand_Ring_Finger</joint>
      <mimicJoint>svh_hand_j16</mimicJoint>
      <hasPID/>
      <multiplier>1.42093</multiplier>
      <offset>0</offset>
      <sensitiveness>0.0</sensitiveness>
      <maxEffort>100.0</maxEffort>
      <robotNamespace>/svh/svh_ros_control_node</robotNamespace>
    </plugin>
    <plugin name='svh_hand_j13_mimic_joint_plugin' filename='libroboticsgroup_gazebo_mimic_joint_plugin.so'>
      <joint>svh_hand_Pinky</joint>
      <mimicJoint>svh_hand_j13</mimicJoint>
      <hasPID/>
      <multiplier>1.3588</multiplier>
      <offset>0</offset>
      <sensitiveness>0.0</sensitiveness>
      <maxEffort>100.0</maxEffort>
      <robotNamespace>/svh/svh_ros_control_node</robotNamespace>
    </plugin>
    <plugin name='svh_hand_j17_mimic_joint_plugin' filename='libroboticsgroup_gazebo_mimic_joint_plugin.so'>
      <joint>svh_hand_Pinky</joint>
      <mimicJoint>svh_hand_j17</mimicJoint>
      <hasPID/>
      <multiplier>1.42307</multiplier>
      <offset>0</offset>
      <sensitiveness>0.0</sensitiveness>
      <maxEffort>100.0</maxEffort>
      <robotNamespace>/svh/svh_ros_control_node</robotNamespace>
    </plugin>
    <plugin name='svh_hand_index_spread_mimic_joint_plugin' filename='libroboticsgroup_gazebo_mimic_joint_plugin.so'>
      <joint>svh_hand_Finger_Spread</joint>
      <mimicJoint>svh_hand_index_spread</mimicJoint>
      <hasPID/>
      <multiplier>0.5</multiplier>
      <offset>0</offset>
      <sensitiveness>0.0</sensitiveness>
      <maxEffort>100.0</maxEffort>
      <robotNamespace>/svh/svh_ros_control_node</robotNamespace>
    </plugin>
    <plugin name='svh_hand_ring_spread_mimic_joint_plugin' filename='libroboticsgroup_gazebo_mimic_joint_plugin.so'>
      <joint>svh_hand_Finger_Spread</joint>
      <mimicJoint>svh_hand_ring_spread</mimicJoint>
      <hasPID/>
      <multiplier>0.5</multiplier>
      <offset>0</offset>
      <sensitiveness>0.0</sensitiveness>
      <maxEffort>100.0</maxEffort>
      <robotNamespace>/svh/svh_ros_control_node</robotNamespace>
    </plugin>
    <static>0</static>
    <plugin name='ros_control' filename='libgazebo_ros_control.so'>
      <robotNamespace>/ur5e</robotNamespace>
    </plugin>
  </model>
</sdf>
