<?xml version="1.0"?>
<sdf version='1.6'>
  <model name='multiple_robots'>
    <link name='panda_link0'>
      <pose frame=''>0 -5 0 0 -0 0</pose>
      <inertial>
        <pose frame=''>0 0 0 0 -0 0</pose>
        <mass>3.06</mass>
        <inertia>
          <ixx>0.3</ixx>
          <ixy>0</ixy>
          <ixz>0</ixz>
          <iyy>0.3</iyy>
          <iyz>0</iyz>
          <izz>0.3</izz>
        </inertia>
      </inertial>
      <collision name='panda_link0_collision'>
        <pose frame=''>0 0 0 0 -0 0</pose>
        <geometry>
          <mesh>
            <scale>1 1 1</scale>
            <uri>model://iiwa_and_panda/meshes/panda/collision/link0.stl</uri>
          </mesh>
        </geometry>
        <surface>
          <contact>
            <ode/>
          </contact>
          <friction>
            <ode>
              <mu>0.2</mu>
              <mu2>0.2</mu2>
            </ode>
          </friction>
        </surface>
      </collision>
      <visual name='panda_link0_visual'>
        <pose frame=''>0 0 0 0 -0 0</pose>
        <geometry>
          <mesh>
            <scale>1 1 1</scale>
            <uri>model://iiwa_and_panda/meshes/panda/visual/link0.dae</uri>
          </mesh>
        </geometry>
        <material>
          <script>
            <name>Gazebo/White</name>
            <uri>file://media/materials/scripts/gazebo.material</uri>
          </script>
        </material>
      </visual>
      <gravity>1</gravity>
      <velocity_decay/>
    </link>
    <joint name='panda_joint_world' type='fixed'>
      <child>panda_link0</child>
      <parent>world</parent>
    </joint>
    <link name='panda_link1'>
      <pose frame=''>0 -5 0.333 0 -0 0</pose>
      <inertial>
        <pose frame=''>0 0 0 0 -0 0</pose>
        <mass>2.34</mass>
        <inertia>
          <ixx>0.3</ixx>
          <ixy>0</ixy>
          <ixz>0</ixz>
          <iyy>0.3</iyy>
          <iyz>0</iyz>
          <izz>0.3</izz>
        </inertia>
      </inertial>
      <collision name='panda_link1_collision'>
        <pose frame=''>0 0 0 0 -0 0</pose>
        <geometry>
          <mesh>
            <scale>1 1 1</scale>
            <uri>model://iiwa_and_panda/meshes/panda/collision/link1.stl</uri>
          </mesh>
        </geometry>
        <surface>
          <contact>
            <ode/>
          </contact>
          <friction>
            <ode>
              <mu>0.2</mu>
              <mu2>0.2</mu2>
            </ode>
          </friction>
        </surface>
      </collision>
      <visual name='panda_link1_visual'>
        <pose frame=''>0 0 0 0 -0 0</pose>
        <geometry>
          <mesh>
            <scale>1 1 1</scale>
            <uri>model://iiwa_and_panda/meshes/panda/visual/link1.dae</uri>
          </mesh>
        </geometry>
        <material>
          <script>
            <name>Gazebo/White</name>
            <uri>file://media/materials/scripts/gazebo.material</uri>
          </script>
        </material>
      </visual>
      <gravity>1</gravity>
      <velocity_decay/>
    </link>
    <joint name='panda_joint1' type='revolute'>
      <child>panda_link1</child>
      <parent>panda_link0</parent>
      <axis>
        <xyz>0 0 1</xyz>
        <limit>
          <lower>-2.8973</lower>
          <upper>2.8973</upper>
          <effort>87</effort>
          <velocity>2.175</velocity>
        </limit>
        <dynamics>
          <spring_reference>0</spring_reference>
          <spring_stiffness>0</spring_stiffness>
        </dynamics>
        <use_parent_model_frame>1</use_parent_model_frame>
      </axis>
    </joint>
    <link name='panda_link2'>
      <pose frame=''>0 -5 0.333 -1.5708 0 0</pose>
      <inertial>
        <pose frame=''>0 0 0 0 -0 0</pose>
        <mass>2.36</mass>
        <inertia>
          <ixx>0.3</ixx>
          <ixy>0</ixy>
          <ixz>0</ixz>
          <iyy>0.3</iyy>
          <iyz>0</iyz>
          <izz>0.3</izz>
        </inertia>
      </inertial>
      <collision name='panda_link2_collision'>
        <pose frame=''>0 0 0 0 -0 0</pose>
        <geometry>
          <cylinder>
            <length>0.12</length>
            <radius>0.06</radius>
          </cylinder>
        </geometry>
        <surface>
          <contact>
            <ode/>
          </contact>
          <friction>
            <ode>
              <mu>0.2</mu>
              <mu2>0.2</mu2>
            </ode>
          </friction>
        </surface>
      </collision>
      <collision name='panda_link2_collision_1'>
        <pose frame=''>0 0 -0.06 0 -0 0</pose>
        <geometry>
          <sphere>
            <radius>0.06</radius>
          </sphere>
        </geometry>
        <surface>
          <contact>
            <ode/>
          </contact>
          <friction>
            <ode>
              <mu>0.2</mu>
              <mu2>0.2</mu2>
            </ode>
          </friction>
        </surface>
      </collision>
      <collision name='panda_link2_collision_2'>
        <pose frame=''>0 0 0.06 0 -0 0</pose>
        <geometry>
          <sphere>
            <radius>0.06</radius>
          </sphere>
        </geometry>
        <surface>
          <contact>
            <ode/>
          </contact>
          <friction>
            <ode>
              <mu>0.2</mu>
              <mu2>0.2</mu2>
            </ode>
          </friction>
        </surface>
      </collision>
      <visual name='panda_link2_visual'>
        <pose frame=''>0 0 0 0 -0 0</pose>
        <geometry>
          <mesh>
            <scale>1 1 1</scale>
            <uri>model://iiwa_and_panda/meshes/panda/visual/link2.dae</uri>
          </mesh>
        </geometry>
        <material>
          <script>
            <name>Gazebo/White</name>
            <uri>file://media/materials/scripts/gazebo.material</uri>
          </script>
        </material>
      </visual>
      <gravity>1</gravity>
      <velocity_decay/>
    </link>
    <joint name='panda_joint2' type='revolute'>
      <child>panda_link2</child>
      <parent>panda_link1</parent>
      <axis>
        <xyz>0 1 0</xyz>
        <limit>
          <lower>-1.7628</lower>
          <upper>1.7628</upper>
          <effort>87</effort>
          <velocity>2.175</velocity>
        </limit>
        <dynamics>
          <spring_reference>0</spring_reference>
          <spring_stiffness>0</spring_stiffness>
        </dynamics>
        <use_parent_model_frame>1</use_parent_model_frame>
      </axis>
    </joint>
    <link name='panda_link3'>
      <pose frame=''>0 -5 0.649 0 -0 0</pose>
      <inertial>
        <pose frame=''>0 0 0 0 -0 0</pose>
        <mass>2.38</mass>
        <inertia>
          <ixx>0.3</ixx>
          <ixy>0</ixy>
          <ixz>0</ixz>
          <iyy>0.3</iyy>
          <iyz>0</iyz>
          <izz>0.3</izz>
        </inertia>
      </inertial>
      <collision name='panda_link3_collision'>
        <pose frame=''>0 0 -0.145 0 -0 0</pose>
        <geometry>
          <cylinder>
            <length>0.15</length>
            <radius>0.06</radius>
          </cylinder>
        </geometry>
        <surface>
          <contact>
            <ode/>
          </contact>
          <friction>
            <ode>
              <mu>0.2</mu>
              <mu2>0.2</mu2>
            </ode>
          </friction>
        </surface>
      </collision>
      <collision name='panda_link3_collision_1'>
        <pose frame=''>0 0 -0.22 0 -0 0</pose>
        <geometry>
          <sphere>
            <radius>0.06</radius>
          </sphere>
        </geometry>
        <surface>
          <contact>
            <ode/>
          </contact>
          <friction>
            <ode>
              <mu>0.2</mu>
              <mu2>0.2</mu2>
            </ode>
          </friction>
        </surface>
      </collision>
      <collision name='panda_link3_collision_2'>
        <pose frame=''>0 0 -0.07 0 -0 0</pose>
        <geometry>
          <sphere>
            <radius>0.06</radius>
          </sphere>
        </geometry>
        <surface>
          <contact>
            <ode/>
          </contact>
          <friction>
            <ode>
              <mu>0.2</mu>
              <mu2>0.2</mu2>
            </ode>
          </friction>
        </surface>
      </collision>
      <visual name='panda_link3_visual'>
        <pose frame=''>0 0 0 0 -0 0</pose>
        <geometry>
          <mesh>
            <scale>1 1 1</scale>
            <uri>model://iiwa_and_panda/meshes/panda/visual/link3.dae</uri>
          </mesh>
        </geometry>
        <material>
          <script>
            <name>Gazebo/White</name>
            <uri>file://media/materials/scripts/gazebo.material</uri>
          </script>
        </material>
      </visual>
      <gravity>1</gravity>
      <velocity_decay/>
    </link>
    <joint name='panda_joint3' type='revolute'>
      <child>panda_link3</child>
      <parent>panda_link2</parent>
      <axis>
        <xyz>0 0 1</xyz>
        <limit>
          <lower>-2.8973</lower>
          <upper>2.8973</upper>
          <effort>87</effort>
          <velocity>2.175</velocity>
        </limit>
        <dynamics>
          <spring_reference>0</spring_reference>
          <spring_stiffness>0</spring_stiffness>
        </dynamics>
        <use_parent_model_frame>1</use_parent_model_frame>
      </axis>
    </joint>
    <link name='panda_link4'>
      <pose frame=''>0.0825 -5 0.649 1.5708 -0 0</pose>
      <inertial>
        <pose frame=''>0 0 0 0 -0 0</pose>
        <mass>2.43</mass>
        <inertia>
          <ixx>0.3</ixx>
          <ixy>0</ixy>
          <ixz>0</ixz>
          <iyy>0.3</iyy>
          <iyz>0</iyz>
          <izz>0.3</izz>
        </inertia>
      </inertial>
      <collision name='panda_link4_collision'>
        <pose frame=''>0 0 0 0 -0 0</pose>
        <geometry>
          <cylinder>
            <length>0.12</length>
            <radius>0.06</radius>
          </cylinder>
        </geometry>
        <surface>
          <contact>
            <ode/>
          </contact>
          <friction>
            <ode>
              <mu>0.2</mu>
              <mu2>0.2</mu2>
            </ode>
          </friction>
        </surface>
      </collision>
      <collision name='panda_link4_collision_1'>
        <pose frame=''>0 0 0.06 0 -0 0</pose>
        <geometry>
          <sphere>
            <radius>0.06</radius>
          </sphere>
        </geometry>
        <surface>
          <contact>
            <ode/>
          </contact>
          <friction>
            <ode>
              <mu>0.2</mu>
              <mu2>0.2</mu2>
            </ode>
          </friction>
        </surface>
      </collision>
      <collision name='panda_link4_collision_2'>
        <pose frame=''>0 0 -0.06 0 -0 0</pose>
        <geometry>
          <sphere>
            <radius>0.06</radius>
          </sphere>
        </geometry>
        <surface>
          <contact>
            <ode/>
          </contact>
          <friction>
            <ode>
              <mu>0.2</mu>
              <mu2>0.2</mu2>
            </ode>
          </friction>
        </surface>
      </collision>
      <visual name='panda_link4_visual'>
        <pose frame=''>0 0 0 0 -0 0</pose>
        <geometry>
          <mesh>
            <scale>1 1 1</scale>
            <uri>model://iiwa_and_panda/meshes/panda/visual/link4.dae</uri>
          </mesh>
        </geometry>
        <material>
          <script>
            <name>Gazebo/White</name>
            <uri>file://media/materials/scripts/gazebo.material</uri>
          </script>
        </material>
      </visual>
      <gravity>1</gravity>
      <velocity_decay/>
    </link>
    <joint name='panda_joint4' type='revolute'>
      <child>panda_link4</child>
      <parent>panda_link3</parent>
      <axis>
        <xyz>0 -1 0</xyz>
        <limit>
          <lower>-3.0718</lower>
          <upper>-0.0698</upper>
          <effort>87</effort>
          <velocity>2.175</velocity>
        </limit>
        <dynamics>
          <spring_reference>0</spring_reference>
          <spring_stiffness>0</spring_stiffness>
        </dynamics>
        <use_parent_model_frame>1</use_parent_model_frame>
      </axis>
    </joint>
    <link name='panda_link5'>
      <pose frame=''>-0 -5 1.033 0 -0 0</pose>
      <inertial>
        <pose frame=''>0 0 0 0 -0 0</pose>
        <mass>3.5</mass>
        <inertia>
          <ixx>0.3</ixx>
          <ixy>0</ixy>
          <ixz>0</ixz>
          <iyy>0.3</iyy>
          <iyz>0</iyz>
          <izz>0.3</izz>
        </inertia>
      </inertial>
      <collision name='panda_link5_collision'>
        <pose frame=''>0 0 -0.26 0 -0 0</pose>
        <geometry>
          <cylinder>
            <length>0.1</length>
            <radius>0.06</radius>
          </cylinder>
        </geometry>
        <surface>
          <contact>
            <ode/>
          </contact>
          <friction>
            <ode>
              <mu>0.2</mu>
              <mu2>0.2</mu2>
            </ode>
          </friction>
        </surface>
      </collision>
      <collision name='panda_link5_collision_1'>
        <pose frame=''>0 0 -0.31 0 -0 0</pose>
        <geometry>
          <sphere>
            <radius>0.06</radius>
          </sphere>
        </geometry>
        <surface>
          <contact>
            <ode/>
          </contact>
          <friction>
            <ode>
              <mu>0.2</mu>
              <mu2>0.2</mu2>
            </ode>
          </friction>
        </surface>
      </collision>
      <collision name='panda_link5_collision_2'>
        <pose frame=''>0 0 -0.21 0 -0 0</pose>
        <geometry>
          <sphere>
            <radius>0.06</radius>
          </sphere>
        </geometry>
        <surface>
          <contact>
            <ode/>
          </contact>
          <friction>
            <ode>
              <mu>0.2</mu>
              <mu2>0.2</mu2>
            </ode>
          </friction>
        </surface>
      </collision>
      <collision name='panda_link5_collision_3'>
        <pose frame=''>0 0.08 -0.13 0 -0 0</pose>
        <geometry>
          <cylinder>
            <length>0.14</length>
            <radius>0.025</radius>
          </cylinder>
        </geometry>
        <surface>
          <contact>
            <ode/>
          </contact>
          <friction>
            <ode>
              <mu>0.2</mu>
              <mu2>0.2</mu2>
            </ode>
          </friction>
        </surface>
      </collision>
      <collision name='panda_link5_collision_4'>
        <pose frame=''>0 0.08 -0.06 0 -0 0</pose>
        <geometry>
          <sphere>
            <radius>0.025</radius>
          </sphere>
        </geometry>
        <surface>
          <contact>
            <ode/>
          </contact>
          <friction>
            <ode>
              <mu>0.2</mu>
              <mu2>0.2</mu2>
            </ode>
          </friction>
        </surface>
      </collision>
      <collision name='panda_link5_collision_5'>
        <pose frame=''>0 0.08 -0.2 0 -0 0</pose>
        <geometry>
          <sphere>
            <radius>0.025</radius>
          </sphere>
        </geometry>
        <surface>
          <contact>
            <ode/>
          </contact>
          <friction>
            <ode>
              <mu>0.2</mu>
              <mu2>0.2</mu2>
            </ode>
          </friction>
        </surface>
      </collision>
      <visual name='panda_link5_visual'>
        <pose frame=''>0 0 0 0 -0 0</pose>
        <geometry>
          <mesh>
            <scale>1 1 1</scale>
            <uri>model://iiwa_and_panda/meshes/panda/visual/link5.dae</uri>
          </mesh>
        </geometry>
        <material>
          <script>
            <name>Gazebo/White</name>
            <uri>file://media/materials/scripts/gazebo.material</uri>
          </script>
        </material>
      </visual>
      <gravity>1</gravity>
      <velocity_decay/>
    </link>
    <joint name='panda_joint5' type='revolute'>
      <child>panda_link5</child>
      <parent>panda_link4</parent>
      <axis>
        <xyz>0 0 1</xyz>
        <limit>
          <lower>-2.8973</lower>
          <upper>2.8973</upper>
          <effort>12</effort>
          <velocity>2.61</velocity>
        </limit>
        <dynamics>
          <spring_reference>0</spring_reference>
          <spring_stiffness>0</spring_stiffness>
        </dynamics>
        <use_parent_model_frame>1</use_parent_model_frame>
      </axis>
    </joint>
    <link name='panda_link6'>
      <pose frame=''>-0 -5 1.033 1.5708 -0 0</pose>
      <inertial>
        <pose frame=''>0 0 0 0 -0 0</pose>
        <mass>1.47</mass>
        <inertia>
          <ixx>0.3</ixx>
          <ixy>0</ixy>
          <ixz>0</ixz>
          <iyy>0.3</iyy>
          <iyz>0</iyz>
          <izz>0.3</izz>
        </inertia>
      </inertial>
      <collision name='panda_link6_collision'>
        <pose frame=''>0 0 -0.03 0 -0 0</pose>
        <geometry>
          <cylinder>
            <length>0.08</length>
            <radius>0.05</radius>
          </cylinder>
        </geometry>
        <surface>
          <contact>
            <ode/>
          </contact>
          <friction>
            <ode>
              <mu>0.2</mu>
              <mu2>0.2</mu2>
            </ode>
          </friction>
        </surface>
      </collision>
      <collision name='panda_link6_collision_1'>
        <pose frame=''>0 0 0.01 0 -0 0</pose>
        <geometry>
          <sphere>
            <radius>0.05</radius>
          </sphere>
        </geometry>
        <surface>
          <contact>
            <ode/>
          </contact>
          <friction>
            <ode>
              <mu>0.2</mu>
              <mu2>0.2</mu2>
            </ode>
          </friction>
        </surface>
      </collision>
      <collision name='panda_link6_collision_2'>
        <pose frame=''>0 0 -0.07 0 -0 0</pose>
        <geometry>
          <sphere>
            <radius>0.05</radius>
          </sphere>
        </geometry>
        <surface>
          <contact>
            <ode/>
          </contact>
          <friction>
            <ode>
              <mu>0.2</mu>
              <mu2>0.2</mu2>
            </ode>
          </friction>
        </surface>
      </collision>
      <visual name='panda_link6_visual'>
        <pose frame=''>0 0 0 0 -0 0</pose>
        <geometry>
          <mesh>
            <scale>1 1 1</scale>
            <uri>model://iiwa_and_panda/meshes/panda/visual/link6.dae</uri>
          </mesh>
        </geometry>
        <material>
          <script>
            <name>Gazebo/White</name>
            <uri>file://media/materials/scripts/gazebo.material</uri>
          </script>
        </material>
      </visual>
      <gravity>1</gravity>
      <velocity_decay/>
    </link>
    <joint name='panda_joint6' type='revolute'>
      <child>panda_link6</child>
      <parent>panda_link5</parent>
      <axis>
        <xyz>0 -1 0</xyz>
        <limit>
          <lower>-0.0175</lower>
          <upper>3.7525</upper>
          <effort>12</effort>
          <velocity>2.61</velocity>
        </limit>
        <dynamics>
          <spring_reference>0</spring_reference>
          <spring_stiffness>0</spring_stiffness>
        </dynamics>
        <use_parent_model_frame>1</use_parent_model_frame>
      </axis>
    </joint>
    <link name='panda_link7'>
      <pose frame=''>0.088 -5 1.033 3.14159 -0 0</pose>
      <inertial>
        <pose frame=''>0 0 0.076525 0 -0 0</pose>
        <mass>1.58</mass>
        <inertia>
          <ixx>0.703685</ixx>
          <ixy>0</ixy>
          <ixz>0</ixz>
          <iyy>0.703685</iyy>
          <iyz>0</iyz>
          <izz>0.7</izz>
        </inertia>
      </inertial>
      <collision name='panda_link7_collision'>
        <pose frame=''>0 0 0.01 0 -0 0</pose>
        <geometry>
          <cylinder>
            <length>0.14</length>
            <radius>0.04</radius>
          </cylinder>
        </geometry>
        <surface>
          <contact>
            <ode/>
          </contact>
          <friction>
            <ode>
              <mu>0.2</mu>
              <mu2>0.2</mu2>
            </ode>
          </friction>
        </surface>
      </collision>
      <collision name='panda_link7_collision_1'>
        <pose frame=''>0 0 0.08 0 -0 0</pose>
        <geometry>
          <sphere>
            <radius>0.04</radius>
          </sphere>
        </geometry>
        <surface>
          <contact>
            <ode/>
          </contact>
          <friction>
            <ode>
              <mu>0.2</mu>
              <mu2>0.2</mu2>
            </ode>
          </friction>
        </surface>
      </collision>
      <collision name='panda_link7_collision_2'>
        <pose frame=''>0 0 -0.06 0 -0 0</pose>
        <geometry>
          <sphere>
            <radius>0.04</radius>
          </sphere>
        </geometry>
        <surface>
          <contact>
            <ode/>
          </contact>
          <friction>
            <ode>
              <mu>0.2</mu>
              <mu2>0.2</mu2>
            </ode>
          </friction>
        </surface>
      </collision>
      <collision name='panda_link7_fixed_joint_lump__panda_hand_collision_3'>
        <pose frame=''>0 0 0.107 0 0 -0.785398</pose>
        <geometry>
          <mesh>
            <scale>1 1 1</scale>
            <uri>model://iiwa_and_panda/meshes/panda/collision/hand.stl</uri>
          </mesh>
        </geometry>
        <surface>
          <contact>
            <ode/>
          </contact>
          <friction>
            <ode>
              <mu>0.2</mu>
              <mu2>0.2</mu2>
            </ode>
          </friction>
        </surface>
      </collision>
      <visual name='panda_link7_visual'>
        <pose frame=''>0 0 0 0 -0 0</pose>
        <geometry>
          <mesh>
            <scale>1 1 1</scale>
            <uri>model://iiwa_and_panda/meshes/panda/visual/link7.dae</uri>
          </mesh>
        </geometry>
        <material>
          <script>
            <name>Gazebo/Grey</name>
            <uri>file://media/materials/scripts/gazebo.material</uri>
          </script>
        </material>
      </visual>
      <visual name='panda_link7_fixed_joint_lump__panda_hand_visual_1'>
        <pose frame=''>0 0 0.107 0 0 -0.785398</pose>
        <geometry>
          <mesh>
            <scale>1 1 1</scale>
            <uri>model://iiwa_and_panda/meshes/panda/visual/hand.dae</uri>
          </mesh>
        </geometry>
        <material>
          <script>
            <name>Gazebo/Grey</name>
            <uri>file://media/materials/scripts/gazebo.material</uri>
          </script>
        </material>
      </visual>
      <velocity_decay/>
      <velocity_decay/>
      <gravity>1</gravity>
      <velocity_decay/>
    </link>
    <joint name='panda_joint7' type='revolute'>
      <child>panda_link7</child>
      <parent>panda_link6</parent>
      <axis>
        <xyz>0 -0 -1</xyz>
        <limit>
          <lower>-2.8973</lower>
          <upper>2.8973</upper>
          <effort>12</effort>
          <velocity>2.61</velocity>
        </limit>
        <dynamics>
          <spring_reference>0</spring_reference>
          <spring_stiffness>0</spring_stiffness>
        </dynamics>
        <use_parent_model_frame>1</use_parent_model_frame>
      </axis>
    </joint>
    <link name='panda_leftfinger'>
      <pose frame=''>0.088 -5 0.8676 3.14159 0 0.785398</pose>
      <inertial>
        <pose frame=''>0 0 0 0 -0 0</pose>
        <mass>0.68</mass>
        <inertia>
          <ixx>0.1</ixx>
          <ixy>0</ixy>
          <ixz>0</ixz>
          <iyy>0.1</iyy>
          <iyz>0</iyz>
          <izz>0.1</izz>
        </inertia>
      </inertial>
      <visual name='panda_leftfinger_visual'>
        <pose frame=''>0 0 0 0 -0 0</pose>
        <geometry>
          <mesh>
            <scale>1 1 1</scale>
            <uri>model://iiwa_and_panda/meshes/panda/visual/finger.dae</uri>
          </mesh>
        </geometry>
        <material>
          <script>
            <name>Gazebo/Grey</name>
            <uri>file://media/materials/scripts/gazebo.material</uri>
          </script>
        </material>
      </visual>
      <gravity>1</gravity>
      <velocity_decay/>
    </link>
    <joint name='panda_finger_joint1' type='prismatic'>
      <child>panda_leftfinger</child>
      <parent>panda_link7</parent>
      <axis>
        <xyz>0.707107 -0.707107 0</xyz>
        <limit>
          <lower>0</lower>
          <upper>0.04</upper>
          <effort>20</effort>
          <velocity>0.2</velocity>
        </limit>
        <dynamics>
          <spring_reference>0</spring_reference>
          <spring_stiffness>0</spring_stiffness>
        </dynamics>
        <use_parent_model_frame>1</use_parent_model_frame>
      </axis>
    </joint>
    <link name='panda_rightfinger'>
      <pose frame=''>0.088 -5 0.8676 3.14159 0 0.785398</pose>
      <inertial>
        <pose frame=''>0 0 0 0 -0 0</pose>
        <mass>0.68</mass>
        <inertia>
          <ixx>0.1</ixx>
          <ixy>0</ixy>
          <ixz>0</ixz>
          <iyy>0.1</iyy>
          <iyz>0</iyz>
          <izz>0.1</izz>
        </inertia>
      </inertial>
      <visual name='panda_rightfinger_visual'>
        <pose frame=''>0 0 0 0 -0 -3.14159</pose>
        <geometry>
          <mesh>
            <scale>1 1 1</scale>
            <uri>model://iiwa_and_panda/meshes/panda/visual/finger.dae</uri>
          </mesh>
        </geometry>
        <material>
          <script>
            <name>Gazebo/Grey</name>
            <uri>file://media/materials/scripts/gazebo.material</uri>
          </script>
        </material>
      </visual>
      <gravity>1</gravity>
      <velocity_decay/>
    </link>
    <joint name='panda_finger_joint2' type='prismatic'>
      <child>panda_rightfinger</child>
      <parent>panda_link7</parent>
      <axis>
        <xyz>-0.707107 0.707107 -0</xyz>
        <limit>
          <lower>0</lower>
          <upper>0.04</upper>
          <effort>20</effort>
          <velocity>0.2</velocity>
        </limit>
        <dynamics>
          <spring_reference>0</spring_reference>
          <spring_stiffness>0</spring_stiffness>
        </dynamics>
        <use_parent_model_frame>1</use_parent_model_frame>
      </axis>
    </joint>
    <link name='iiwa_link_0'>
      <pose frame=''>0 0 0 0 -0 0</pose>
      <inertial>
        <pose frame=''>-0.1 0 0.07 0 -0 0</pose>
        <mass>5</mass>
        <inertia>
          <ixx>0.05</ixx>
          <ixy>0</ixy>
          <ixz>0</ixz>
          <iyy>0.06</iyy>
          <iyz>0</iyz>
          <izz>0.03</izz>
        </inertia>
      </inertial>
      <collision name='iiwa_link_0_collision'>
        <pose frame=''>0 0 0 0 -0 0</pose>
        <geometry>
          <mesh>
            <scale>1 1 1</scale>
            <uri>model://iiwa_and_panda/meshes/iiwa/collision/link_0.dae</uri>
          </mesh>
        </geometry>
        <surface>
          <contact>
            <ode/>
          </contact>
          <friction>
            <ode>
              <mu>0.2</mu>
              <mu2>0.2</mu2>
            </ode>
          </friction>
        </surface>
      </collision>
      <visual name='iiwa_link_0_visual'>
        <pose frame=''>0 0 0 0 -0 0</pose>
        <geometry>
          <mesh>
            <scale>1 1 1</scale>
            <uri>model://iiwa_and_panda/meshes/iiwa/visual/link_0.dae</uri>
          </mesh>
        </geometry>
        <material>
          <script>
            <name>Gazebo/Grey</name>
            <uri>file://media/materials/scripts/gazebo.material</uri>
          </script>
        </material>
      </visual>
      <gravity>1</gravity>
      <velocity_decay/>
    </link>
    <joint name='world_iiwa_joint' type='fixed'>
      <child>iiwa_link_0</child>
      <parent>world</parent>
    </joint>
    <link name='iiwa_link_1'>
      <pose frame=''>0 0 0.1575 0 -0 0</pose>
      <inertial>
        <pose frame=''>0 -0.03 0.12 0 -0 0</pose>
        <mass>4</mass>
        <inertia>
          <ixx>0.1</ixx>
          <ixy>0</ixy>
          <ixz>0</ixz>
          <iyy>0.09</iyy>
          <iyz>0</iyz>
          <izz>0.02</izz>
        </inertia>
      </inertial>
      <collision name='iiwa_link_1_collision'>
        <pose frame=''>0 0 0 0 -0 0</pose>
        <geometry>
          <mesh>
            <scale>1 1 1</scale>
            <uri>model://iiwa_and_panda/meshes/iiwa/collision/link_1.dae</uri>
          </mesh>
        </geometry>
        <surface>
          <contact>
            <ode/>
          </contact>
          <friction>
            <ode>
              <mu>0.2</mu>
              <mu2>0.2</mu2>
            </ode>
          </friction>
        </surface>
      </collision>
      <visual name='iiwa_link_1_visual'>
        <pose frame=''>0 0 0 0 -0 0</pose>
        <geometry>
          <mesh>
            <scale>1 1 1</scale>
            <uri>model://iiwa_and_panda/meshes/iiwa/visual/link_1.dae</uri>
          </mesh>
        </geometry>
        <material>
          <script>
            <name>Gazebo/Orange</name>
            <uri>file://media/materials/scripts/gazebo.material</uri>
          </script>
        </material>
      </visual>
      <gravity>1</gravity>
      <velocity_decay/>
    </link>
    <joint name='iiwa_joint_1' type='revolute'>
      <child>iiwa_link_1</child>
      <parent>iiwa_link_0</parent>
      <axis>
        <xyz>0 0 1</xyz>
        <limit>
          <lower>-2.96706</lower>
          <upper>2.96706</upper>
          <effort>300</effort>
          <velocity>10</velocity>
        </limit>
        <dynamics>
          <damping>0</damping>
          <friction>0</friction>
          <spring_reference>0</spring_reference>
          <spring_stiffness>0</spring_stiffness>
        </dynamics>
        <use_parent_model_frame>1</use_parent_model_frame>
      </axis>
    </joint>
    <link name='iiwa_link_2'>
      <pose frame=''>0 0 0.36 1.5708 -0 -3.14159</pose>
      <inertial>
        <pose frame=''>0.0003 0.059 0.042 0 -0 0</pose>
        <mass>0.4</mass>
        <inertia>
          <ixx>0.05</ixx>
          <ixy>0</ixy>
          <ixz>0</ixz>
          <iyy>0.018</iyy>
          <iyz>0</iyz>
          <izz>0.044</izz>
        </inertia>
      </inertial>
      <collision name='iiwa_link_2_collision'>
        <pose frame=''>0 0 0 0 -0 0</pose>
        <geometry>
          <mesh>
            <scale>1 1 1</scale>
            <uri>model://iiwa_and_panda/meshes/iiwa/collision/link_2.dae</uri>
          </mesh>
        </geometry>
        <surface>
          <contact>
            <ode/>
          </contact>
          <friction>
            <ode>
              <mu>0.2</mu>
              <mu2>0.2</mu2>
            </ode>
          </friction>
        </surface>
      </collision>
      <visual name='iiwa_link_2_visual'>
        <pose frame=''>0 0 0 0 -0 0</pose>
        <geometry>
          <mesh>
            <scale>1 1 1</scale>
            <uri>model://iiwa_and_panda/meshes/iiwa/visual/link_2.dae</uri>
          </mesh>
        </geometry>
        <material>
          <script>
            <name>Gazebo/Orange</name>
            <uri>file://media/materials/scripts/gazebo.material</uri>
          </script>
        </material>
      </visual>
      <gravity>1</gravity>
      <velocity_decay/>
    </link>
    <joint name='iiwa_joint_2' type='revolute'>
      <child>iiwa_link_2</child>
      <parent>iiwa_link_1</parent>
      <axis>
        <xyz>-0 1 0</xyz>
        <limit>
          <lower>-2.0944</lower>
          <upper>2.0944</upper>
          <effort>300</effort>
          <velocity>10</velocity>
        </limit>
        <dynamics>
          <damping>0</damping>
          <friction>0</friction>
          <spring_reference>0</spring_reference>
          <spring_stiffness>0</spring_stiffness>
        </dynamics>
        <use_parent_model_frame>1</use_parent_model_frame>
      </axis>
    </joint>
    <link name='iiwa_link_3'>
      <pose frame=''>0 -0 0.5645 0 0 0</pose>
      <inertial>
        <pose frame=''>0 0.03 0.13 0 -0 0</pose>
        <mass>0.3</mass>
        <inertia>
          <ixx>0.08</ixx>
          <ixy>0</ixy>
          <ixz>0</ixz>
          <iyy>0.075</iyy>
          <iyz>0</iyz>
          <izz>0.01</izz>
        </inertia>
      </inertial>
      <collision name='iiwa_link_3_collision'>
        <pose frame=''>0 0 0 0 -0 0</pose>
        <geometry>
          <mesh>
            <scale>1 1 1</scale>
            <uri>model://iiwa_and_panda/meshes/iiwa/collision/link_3.dae</uri>
          </mesh>
        </geometry>
        <surface>
          <contact>
            <ode/>
          </contact>
          <friction>
            <ode>
              <mu>0.2</mu>
              <mu2>0.2</mu2>
            </ode>
          </friction>
        </surface>
      </collision>
      <visual name='iiwa_link_3_visual'>
        <pose frame=''>0 0 0 0 -0 0</pose>
        <geometry>
          <mesh>
            <scale>1 1 1</scale>
            <uri>model://iiwa_and_panda/meshes/iiwa/visual/link_3.dae</uri>
          </mesh>
        </geometry>
        <material>
          <script>
            <name>Gazebo/Orange</name>
            <uri>file://media/materials/scripts/gazebo.material</uri>
          </script>
        </material>
      </visual>
      <gravity>1</gravity>
      <velocity_decay/>
    </link>
    <joint name='iiwa_joint_3' type='revolute'>
      <child>iiwa_link_3</child>
      <parent>iiwa_link_2</parent>
      <axis>
        <xyz>0 0 1</xyz>
        <limit>
          <lower>-2.96706</lower>
          <upper>2.96706</upper>
          <effort>300</effort>
          <velocity>10</velocity>
        </limit>
        <dynamics>
          <damping>0</damping>
          <friction>0</friction>
          <spring_reference>0</spring_reference>
          <spring_stiffness>0</spring_stiffness>
        </dynamics>
        <use_parent_model_frame>1</use_parent_model_frame>
      </axis>
    </joint>
    <link name='iiwa_link_4'>
      <pose frame=''>0 -0 0.78 1.5708 0 0</pose>
      <inertial>
        <pose frame=''>0 0.067 0.034 0 -0 0</pose>
        <mass>0.27</mass>
        <inertia>
          <ixx>0.03</ixx>
          <ixy>0</ixy>
          <ixz>0</ixz>
          <iyy>0.01</iyy>
          <iyz>0</iyz>
          <izz>0.029</izz>
        </inertia>
      </inertial>
      <collision name='iiwa_link_4_collision'>
        <pose frame=''>0 0 0 0 -0 0</pose>
        <geometry>
          <mesh>
            <scale>1 1 1</scale>
            <uri>model://iiwa_and_panda/meshes/iiwa/collision/link_4.dae</uri>
          </mesh>
        </geometry>
        <surface>
          <contact>
            <ode/>
          </contact>
          <friction>
            <ode>
              <mu>0.2</mu>
              <mu2>0.2</mu2>
            </ode>
          </friction>
        </surface>
      </collision>
      <visual name='iiwa_link_4_visual'>
        <pose frame=''>0 0 0 0 -0 0</pose>
        <geometry>
          <mesh>
            <scale>1 1 1</scale>
            <uri>model://iiwa_and_panda/meshes/iiwa/visual/link_4.dae</uri>
          </mesh>
        </geometry>
        <material>
          <script>
            <name>Gazebo/Orange</name>
            <uri>file://media/materials/scripts/gazebo.material</uri>
          </script>
        </material>
      </visual>
      <gravity>1</gravity>
      <velocity_decay/>
    </link>
    <joint name='iiwa_joint_4' type='revolute'>
      <child>iiwa_link_4</child>
      <parent>iiwa_link_3</parent>
      <axis>
        <xyz>0 -1 0</xyz>
        <limit>
          <lower>-2.0944</lower>
          <upper>2.0944</upper>
          <effort>300</effort>
          <velocity>10</velocity>
        </limit>
        <dynamics>
          <damping>0</damping>
          <friction>0</friction>
          <spring_reference>0</spring_reference>
          <spring_stiffness>0</spring_stiffness>
        </dynamics>
        <use_parent_model_frame>1</use_parent_model_frame>
      </axis>
    </joint>
    <link name='iiwa_link_5'>
      <pose frame=''>0 -0 0.9645 0 -0 -3.14159</pose>
      <inertial>
        <pose frame=''>0.0001 0.021 0.076 0 -0 0</pose>
        <mass>0.17</mass>
        <inertia>
          <ixx>0.02</ixx>
          <ixy>0</ixy>
          <ixz>0</ixz>
          <iyy>0.018</iyy>
          <iyz>0</iyz>
          <izz>0.005</izz>
        </inertia>
      </inertial>
      <collision name='iiwa_link_5_collision'>
        <pose frame=''>0 0 0 0 -0 0</pose>
        <geometry>
          <mesh>
            <scale>1 1 1</scale>
            <uri>model://iiwa_and_panda/meshes/iiwa/collision/link_5.dae</uri>
          </mesh>
        </geometry>
        <surface>
          <contact>
            <ode/>
          </contact>
          <friction>
            <ode>
              <mu>0.2</mu>
              <mu2>0.2</mu2>
            </ode>
          </friction>
        </surface>
      </collision>
      <visual name='iiwa_link_5_visual'>
        <pose frame=''>0 0 0 0 -0 0</pose>
        <geometry>
          <mesh>
            <scale>1 1 1</scale>
            <uri>model://iiwa_and_panda/meshes/iiwa/visual/link_5.dae</uri>
          </mesh>
        </geometry>
        <material>
          <script>
            <name>Gazebo/Orange</name>
            <uri>file://media/materials/scripts/gazebo.material</uri>
          </script>
        </material>
      </visual>
      <gravity>1</gravity>
      <velocity_decay/>
    </link>
    <joint name='iiwa_joint_5' type='revolute'>
      <child>iiwa_link_5</child>
      <parent>iiwa_link_4</parent>
      <axis>
        <xyz>0 0 1</xyz>
        <limit>
          <lower>-2.96706</lower>
          <upper>2.96706</upper>
          <effort>300</effort>
          <velocity>10</velocity>
        </limit>
        <dynamics>
          <damping>0</damping>
          <friction>0</friction>
          <spring_reference>0</spring_reference>
          <spring_stiffness>0</spring_stiffness>
        </dynamics>
        <use_parent_model_frame>1</use_parent_model_frame>
      </axis>
    </joint>
    <link name='iiwa_link_6'>
      <pose frame=''>0 0 1.18 1.5708 -0 -3.14159</pose>
      <inertial>
        <pose frame=''>0 0.0006 0.0004 0 -0 0</pose>
        <mass>0.18</mass>
        <inertia>
          <ixx>0.025</ixx>
          <ixy>0</ixy>
          <ixz>0</ixz>
          <iyy>0.0136</iyy>
          <iyz>0</iyz>
          <izz>0.0247</izz>
        </inertia>
      </inertial>
      <collision name='iiwa_link_6_collision'>
        <pose frame=''>0 0 0 0 -0 0</pose>
        <geometry>
          <mesh>
            <scale>1 1 1</scale>
            <uri>model://iiwa_and_panda/meshes/iiwa/collision/link_6.dae</uri>
          </mesh>
        </geometry>
        <surface>
          <contact>
            <ode/>
          </contact>
          <friction>
            <ode>
              <mu>0.2</mu>
              <mu2>0.2</mu2>
            </ode>
          </friction>
        </surface>
      </collision>
      <visual name='iiwa_link_6_visual'>
        <pose frame=''>0 0 0 0 -0 0</pose>
        <geometry>
          <mesh>
            <scale>1 1 1</scale>
            <uri>model://iiwa_and_panda/meshes/iiwa/visual/link_6.dae</uri>
          </mesh>
        </geometry>
        <material>
          <script>
            <name>Gazebo/Orange</name>
            <uri>file://media/materials/scripts/gazebo.material</uri>
          </script>
        </material>
      </visual>
      <gravity>1</gravity>
      <velocity_decay/>
    </link>
    <joint name='iiwa_joint_6' type='revolute'>
      <child>iiwa_link_6</child>
      <parent>iiwa_link_5</parent>
      <axis>
        <xyz>-0 1 -0</xyz>
        <limit>
          <lower>-2.0944</lower>
          <upper>2.0944</upper>
          <effort>300</effort>
          <velocity>10</velocity>
        </limit>
        <dynamics>
          <damping>0</damping>
          <friction>0</friction>
          <spring_reference>0</spring_reference>
          <spring_stiffness>0</spring_stiffness>
        </dynamics>
        <use_parent_model_frame>1</use_parent_model_frame>
      </axis>
    </joint>
    <link name='iiwa_link_7'>
      <pose frame=''>0 0 1.261 0 0 0</pose>
      <inertial>
        <pose frame=''>0 0 0.035625 0 -0 0</pose>
        <mass>0.08</mass>
        <inertia>
          <ixx>0.0101817</ixx>
          <ixy>0</ixy>
          <ixz>0</ixz>
          <iyy>0.0117117</iyy>
          <iyz>-4.37114e-12</iyz>
          <izz>0.0118</izz>
        </inertia>
      </inertial>
      <collision name='iiwa_link_7_collision'>
        <pose frame=''>0 0 0 0 -0 0</pose>
        <geometry>
          <mesh>
            <scale>1 1 1</scale>
            <uri>model://iiwa_and_panda/meshes/iiwa/collision/link_7.dae</uri>
          </mesh>
        </geometry>
        <surface>
          <contact>
            <ode/>
          </contact>
          <friction>
            <ode>
              <mu>0.2</mu>
              <mu2>0.2</mu2>
            </ode>
          </friction>
        </surface>
      </collision>
      <collision name='iiwa_link_7_fixed_joint_lump__base_link_link_collision_1'>
        <pose frame=''>0 -0 0.07 0 -0 0</pose>
        <geometry>
          <mesh>
            <scale>1 1 1</scale>
            <uri>model://iiwa_and_panda/meshes/iiwa/collision/COL_base.dae</uri>
          </mesh>
        </geometry>
      </collision>
      <visual name='iiwa_link_7_visual'>
        <pose frame=''>0 0 0 0 -0 0</pose>
        <geometry>
          <mesh>
            <scale>1 1 1</scale>
            <uri>model://iiwa_and_panda/meshes/iiwa/visual/link_7.dae</uri>
          </mesh>
        </geometry>
        <material>
          <script>
            <name>Gazebo/Grey</name>
            <uri>file://media/materials/scripts/gazebo.material</uri>
          </script>
        </material>
      </visual>
      <visual name='iiwa_link_7_fixed_joint_lump__base_link_link_visual_1'>
        <pose frame=''>0 -0 0.07 0 -0 0</pose>
        <geometry>
          <mesh>
            <scale>1 1 1</scale>
            <uri>model://iiwa_and_panda/meshes/iiwa/visual/VIS_base.dae</uri>
          </mesh>
        </geometry>
      </visual>
      <gravity>1</gravity>
      <velocity_decay/>
    </link>
    <joint name='iiwa_joint_7' type='revolute'>
      <child>iiwa_link_7</child>
      <parent>iiwa_link_6</parent>
      <axis>
        <xyz>0 0 1</xyz>
        <limit>
          <lower>-3.05433</lower>
          <upper>3.05433</upper>
          <effort>300</effort>
          <velocity>10</velocity>
        </limit>
        <dynamics>
          <damping>0</damping>
          <friction>0</friction>
          <spring_reference>0</spring_reference>
          <spring_stiffness>0</spring_stiffness>
        </dynamics>
        <use_parent_model_frame>1</use_parent_model_frame>
      </axis>
      <physics>
        <provide_feedback>1</provide_feedback>
        <ode>
          <provide_feedback>1</provide_feedback>
          <limit>
            <cfm>0</cfm>
            <erp>0.2</erp>
          </limit>
        </ode>
      </physics>
    </joint>
    <link name='gripper_left_link'>
      <pose frame=''>-0.085 -0 1.356 -3.14159 -0 1.5708</pose>
      <inertial>
        <pose frame=''>0 0 0 0 -0 0</pose>
        <mass>0.01</mass>
        <inertia>
          <ixx>0.0002</ixx>
          <ixy>0</ixy>
          <ixz>0</ixz>
          <iyy>0.000195</iyy>
          <iyz>0</iyz>
          <izz>2.1e-05</izz>
        </inertia>
      </inertial>
      <collision name='gripper_left_link_collision'>
        <pose frame=''>0 -0 -0.072 3.14159 0 1.5708</pose>
        <geometry>
          <mesh>
            <scale>1 1 1</scale>
            <uri>model://iiwa_and_panda/meshes/iiwa/collision/COL_gripper_left.dae</uri>
          </mesh>
        </geometry>
      </collision>
      <visual name='gripper_left_link_visual'>
        <pose frame=''>0 -0 -0.072 3.14159 0 1.5708</pose>
        <geometry>
          <mesh>
            <scale>1 1 1</scale>
            <uri>model://iiwa_and_panda/meshes/iiwa/visual/VIS_gripper_left.dae</uri>
          </mesh>
        </geometry>
      </visual>
    </link>
    <joint name='gripper_left_joint' type='prismatic'>
      <child>gripper_left_link</child>
      <parent>iiwa_link_7</parent>
      <axis>
        <xyz>1 -0 -0</xyz>
        <limit>
          <lower>0</lower>
          <upper>0.0704</upper>
          <effort>100</effort>
          <velocity>1</velocity>
        </limit>
        <dynamics>
          <damping>1</damping>
          <friction>0</friction>
          <spring_reference>0</spring_reference>
          <spring_stiffness>0</spring_stiffness>
        </dynamics>
        <use_parent_model_frame>1</use_parent_model_frame>
      </axis>
    </joint>
    <link name='gripper_right_link'>
      <pose frame=''>0.085 -0 1.356 -3.14159 0 -1.5708</pose>
      <inertial>
        <pose frame=''>0 0 0 0 -0 0</pose>
        <mass>0.01</mass>
        <inertia>
          <ixx>0.0002</ixx>
          <ixy>0</ixy>
          <ixz>0</ixz>
          <iyy>0.000195</iyy>
          <iyz>0</iyz>
          <izz>2.1e-05</izz>
        </inertia>
      </inertial>
      <collision name='gripper_right_link_collision'>
        <pose frame=''>-0 -0 -0.072 3.14159 -0 -1.5708</pose>
        <geometry>
          <mesh>
            <scale>1 1 1</scale>
            <uri>model://iiwa_and_panda/meshes/iiwa/collision/COL_gripper_right.dae</uri>
          </mesh>
        </geometry>
      </collision>
      <visual name='gripper_right_link_visual'>
        <pose frame=''>-0 -0 -0.072 3.14159 -0 -1.5708</pose>
        <geometry>
          <mesh>
            <scale>1 1 1</scale>
            <uri>model://iiwa_and_panda/meshes/iiwa/visual/VIS_gripper_right.dae</uri>
          </mesh>
        </geometry>
      </visual>
    </link>
    <joint name='gripper_right_joint' type='prismatic'>
      <child>gripper_right_link</child>
      <parent>iiwa_link_7</parent>
      <axis>
        <xyz>-1 -0 -0</xyz>
        <limit>
          <lower>0</lower>
          <upper>0.0704</upper>
          <effort>100</effort>
          <velocity>1</velocity>
        </limit>
        <dynamics>
          <damping>1</damping>
          <friction>0</friction>
          <spring_reference>0</spring_reference>
          <spring_stiffness>0</spring_stiffness>
        </dynamics>
        <use_parent_model_frame>1</use_parent_model_frame>
      </axis>
    </joint>
    <plugin name='ft_sensor' filename='libgazebo_ros_ft_sensor.so'>
      <updateRate>50.0</updateRate>
      <topicName>/iiwa/state/CartesianWrench</topicName>
      <jointName>iiwa_joint_7</jointName>
    </plugin>
    <plugin name='gazebo_grasp_fix' filename='libgazebo_grasp_fix.so'>
      <arm>
        <arm_name>iiwa</arm_name>
        <palm_link>iiwa_link_7</palm_link>
        <gripper_link>gripper_right_link</gripper_link>
        <gripper_link>gripper_left_link</gripper_link>
      </arm>
      <forces_angle_tolerance>100</forces_angle_tolerance>
      <update_rate>4</update_rate>
      <grip_count_threshold>4</grip_count_threshold>
      <max_grip_count>8</max_grip_count>
      <release_tolerance>0.005</release_tolerance>
      <disable_collisions_on_attach>0</disable_collisions_on_attach>
      <contact_topic>__default_topic__</contact_topic>
    </plugin>
    <plugin name='gazebo_ros_control' filename='libgazebo_ros_control.so'>
      <robotNamespace>/iiwa</robotNamespace>
    </plugin>
    <static>0</static>
    <plugin name='gazebo_ros_control' filename='libgazebo_ros_control.so'>
      <robotNamespace>/panda</robotNamespace>
    </plugin>
  </model>
</sdf>
